{
  "timestamp": "2025-05-29T07:02:59.948507",
  "execution_time": 41.886059045791626,
  "total_tests": 95,
  "total_passed": 60,
  "total_failed": 26,
  "success_rate": 63.1578947368421,
  "overall_success": false,
  "results": {
    "smoke": {
      "success": true,
      "critical_failure": false
    },
    "unit": {
      "category": "unit",
      "description": "Unit Tests - Core Components",
      "success": false,
      "execution_time": 5.700011968612671,
      "statistics": {
        "total": 70,
        "passed": 54,
        "failed": 16,
        "skipped": 0,
        "errors": 0
      },
      "stdout": "============================= test session starts =============================\nplatform win32 -- Python 3.12.1, pytest-8.3.5, pluggy-1.5.0 -- C:\\Program Files\\Python312\\python.exe\ncachedir: .pytest_cache\nmetadata: {'Python': '3.12.1', 'Platform': 'Windows-10-10.0.19045-SP0', 'Packages': {'pytest': '8.3.5', 'pluggy': '1.5.0'}, 'Plugins': {'anyio': '4.8.0', 'asyncio': '0.21.1', 'cov': '4.1.0', 'html': '4.1.1', 'metadata': '3.1.1', 'xdist': '3.7.0'}}\nrootdir: C:\\Users\\Devansh\\Downloads\\intern_application_round1\nconfigfile: pytest.ini\nplugins: anyio-4.8.0, asyncio-0.21.1, cov-4.1.0, html-4.1.1, metadata-3.1.1, xdist-3.7.0\nasyncio: mode=Mode.STRICT\ncollecting ... collected 164 items / 94 deselected / 70 selected\n\ntests/test_analytics.py::TestMetricsAnalyzer::test_analyzer_initialization PASSED [  1%]\ntests/test_analytics.py::TestMetricsAnalyzer::test_calculate_basic_metrics PASSED [  2%]\ntests/test_analytics.py::TestMetricsAnalyzer::test_analyze_session_metrics PASSED [  4%]\ntests/test_analytics.py::TestMetricsAnalyzer::test_calculate_temporal_metrics PASSED [  5%]\ntests/test_analytics.py::TestMetricsAnalyzer::test_calculate_subreddit_metrics PASSED [  7%]\ntests/test_analytics.py::TestMetricsAnalyzer::test_calculate_sentiment_metrics PASSED [  8%]\ntests/test_analytics.py::TestMetricsAnalyzer::test_calculate_engagement_metrics PASSED [ 10%]\ntests/test_analytics.py::TestMetricsAnalyzer::test_detect_trending_topics PASSED [ 11%]\ntests/test_analytics.py::TestMetricsAnalyzer::test_generate_comprehensive_metrics PASSED [ 12%]\ntests/test_analytics.py::TestMetricsAnalyzer::test_empty_mentions_handling PASSED [ 14%]\ntests/test_analytics.py::TestMetricsAnalyzer::test_malformed_data_handling PASSED [ 15%]\ntests/test_analytics.py::TestDataValidator::test_validator_initialization PASSED [ 17%]\ntests/test_analytics.py::TestDataValidator::test_validate_mention_valid_data PASSED [ 18%]\ntests/test_analytics.py::TestDataValidator::test_validate_mention_invalid_data PASSED [ 20%]\ntests/test_database.py::TestDatabaseManager::test_database_initialization PASSED [ 21%]\ntests/test_database.py::TestDatabaseManager::test_create_search_session PASSED [ 22%]\ntests/test_database.py::TestDatabaseManager::test_add_mention FAILED     [ 24%]\ntests/test_database.py::TestDatabaseManager::test_get_mentions_by_session FAILED [ 25%]\ntests/test_database.py::TestDatabaseManager::test_update_search_session PASSED [ 27%]\ntests/test_database.py::TestDatabaseManager::test_get_session_statistics FAILED [ 28%]\ntests/test_database.py::TestDatabaseManager::test_search_mentions FAILED [ 30%]\ntests/test_database.py::TestDatabaseManager::test_get_trending_subreddits FAILED [ 31%]\ntests/test_database.py::TestDatabaseManager::test_get_sentiment_distribution FAILED [ 32%]\ntests/test_database.py::TestDatabaseManager::test_get_time_series_data FAILED [ 34%]\ntests/test_database.py::TestDatabaseManager::test_cleanup_old_sessions PASSED [ 35%]\ntests/test_database.py::TestDatabaseManager::test_database_connection_handling PASSED [ 37%]\ntests/test_database.py::TestDatabaseManager::test_database_error_handling PASSED [ 38%]\ntests/test_database.py::TestDatabaseManager::test_duplicate_mention_handling FAILED [ 40%]\ntests/test_database.py::TestDatabaseManager::test_database_backup_restore FAILED [ 41%]\ntests/test_database.py::TestSearchSession::test_search_session_creation PASSED [ 42%]\ntests/test_database.py::TestSearchSession::test_search_session_relationships FAILED [ 44%]\ntests/test_database.py::TestRedditMention::test_reddit_mention_creation PASSED [ 45%]\ntests/test_database.py::TestRedditMention::test_reddit_mention_validation PASSED [ 47%]\ntests/test_scraper.py::TestRedditScraper::test_scraper_initialization PASSED [ 48%]\ntests/test_scraper.py::TestRedditScraper::test_sanitize_search_term PASSED [ 50%]\ntests/test_scraper.py::TestRedditScraper::test_calculate_relevance_score PASSED [ 51%]\ntests/test_scraper.py::TestScrapingConfiguration::test_build_search_patterns PASSED [ 52%]\ntests/test_scraper.py::TestScrapingConfiguration::test_filter_by_quality PASSED [ 54%]\ntests/test_scraper.py::TestScrapingConfiguration::test_deduplicate_mentions PASSED [ 55%]\ntests/test_scraper.py::TestScrapingConfiguration::test_validate_mention_data PASSED [ 57%]\ntests/test_scraper.py::TestScrapingConfiguration::test_error_handling PASSED [ 58%]\ntests/test_scraper.py::TestScrapingConfiguration::test_rate_limiting_configuration PASSED [ 60%]\ntests/test_ui.py::TestMetricsVisualizer::test_visualizer_initialization PASSED [ 61%]\ntests/test_ui.py::TestMetricsVisualizer::test_create_overview_dashboard PASSED [ 62%]\ntests/test_ui.py::TestMetricsVisualizer::test_create_temporal_analysis FAILED [ 64%]\ntests/test_ui.py::TestMetricsVisualizer::test_create_subreddit_analysis PASSED [ 65%]\ntests/test_ui.py::TestMetricsVisualizer::test_create_engagement_analysis PASSED [ 67%]\ntests/test_ui.py::TestMetricsVisualizer::test_create_sentiment_analysis PASSED [ 68%]\ntests/test_ui.py::TestMetricsVisualizer::test_create_summary_metrics_table PASSED [ 70%]\ntests/test_ui.py::TestMetricsVisualizer::test_empty_data_handling PASSED [ 71%]\ntests/test_ui.py::TestMetricsVisualizer::test_malformed_data_handling FAILED [ 72%]\ntests/test_ui.py::TestMetricsVisualizer::test_color_scheme_consistency PASSED [ 74%]\ntests/test_ui.py::TestMetricsVisualizer::test_chart_interactivity PASSED [ 75%]\ntests/test_ui.py::TestMetricsVisualizer::test_responsive_design PASSED   [ 77%]\ntests/test_ui.py::TestRealTimeMonitor::test_monitor_initialization PASSED [ 78%]\ntests/test_ui.py::TestRealTimeMonitor::test_event_types PASSED           [ 80%]\ntests/test_ui.py::TestRealTimeMonitor::test_emit_search_started PASSED   [ 81%]\ntests/test_ui.py::TestRealTimeMonitor::test_emit_search_progress PASSED  [ 82%]\ntests/test_ui.py::TestRealTimeMonitor::test_emit_search_completed PASSED [ 84%]\ntests/test_ui.py::TestRealTimeMonitor::test_emit_search_failed FAILED    [ 85%]\ntests/test_ui.py::TestRealTimeMonitor::test_emit_mention_found FAILED    [ 87%]\ntests/test_ui.py::TestRealTimeMonitor::test_emit_metrics_updated FAILED  [ 88%]\ntests/test_ui.py::TestRealTimeMonitor::test_emit_cache_hit PASSED        [ 90%]\ntests/test_ui.py::TestRealTimeMonitor::test_emit_system_status PASSED    [ 91%]\ntests/test_ui.py::TestRealTimeMonitor::test_get_connection_stats FAILED  [ 92%]\ntests/test_ui.py::TestRealTimeMonitor::test_progress_callback_initialization PASSED [ 94%]\ntests/test_ui.py::TestRealTimeMonitor::test_progress_callback_execution PASSED [ 95%]\ntests/test_ui.py::TestRealTimeMonitor::test_progress_callback_with_mention PASSED [ 97%]\ntests/test_ui.py::TestRealTimeMonitor::test_multiple_event_emissions PASSED [ 98%]\ntests/test_ui.py::TestRealTimeMonitor::test_event_message_structure PASSED [100%]\n\n================================== FAILURES ===================================\n____________________ TestDatabaseManager.test_add_mention _____________________\ntests\\test_database.py:63: in test_add_mention\n    mention = db_manager.add_mention(mention_data)\nE   TypeError: DatabaseManager.add_mention() missing 1 required positional argument: 'mention_data'\n______________ TestDatabaseManager.test_get_mentions_by_session _______________\ntests\\test_database.py:89: in test_get_mentions_by_session\n    db_manager.add_mention(mention_data)\nE   TypeError: DatabaseManager.add_mention() missing 1 required positional argument: 'mention_data'\n_______________ TestDatabaseManager.test_get_session_statistics _______________\ntests\\test_database.py:131: in test_get_session_statistics\n    db_manager.add_mention(mention_data)\nE   TypeError: DatabaseManager.add_mention() missing 1 required positional argument: 'mention_data'\n__________________ TestDatabaseManager.test_search_mentions ___________________\ntests\\test_database.py:169: in test_search_mentions\n    db_manager.add_mention(high_score_mention)\nE   TypeError: DatabaseManager.add_mention() missing 1 required positional argument: 'mention_data'\n______________ TestDatabaseManager.test_get_trending_subreddits _______________\ntests\\test_database.py:202: in test_get_trending_subreddits\n    db_manager.add_mention(mention_data)\nE   TypeError: DatabaseManager.add_mention() missing 1 required positional argument: 'mention_data'\n_____________ TestDatabaseManager.test_get_sentiment_distribution _____________\ntests\\test_database.py:236: in test_get_sentiment_distribution\n    db_manager.add_mention(mention_data)\nE   TypeError: DatabaseManager.add_mention() missing 1 required positional argument: 'mention_data'\n________________ TestDatabaseManager.test_get_time_series_data ________________\ntests\\test_database.py:267: in test_get_time_series_data\n    db_manager.add_mention(mention_data)\nE   TypeError: DatabaseManager.add_mention() missing 1 required positional argument: 'mention_data'\n_____________ TestDatabaseManager.test_duplicate_mention_handling _____________\ntests\\test_database.py:353: in test_duplicate_mention_handling\n    mention1 = db_manager.add_mention(mention_data)\nE   TypeError: DatabaseManager.add_mention() missing 1 required positional argument: 'mention_data'\n______________ TestDatabaseManager.test_database_backup_restore _______________\ntests\\test_database.py:380: in test_database_backup_restore\n    db_manager.add_mention(test_mention)\nE   TypeError: DatabaseManager.add_mention() missing 1 required positional argument: 'mention_data'\n_____________ TestSearchSession.test_search_session_relationships _____________\ntests\\test_database.py:430: in test_search_session_relationships\n    db_manager.add_mention(mention_data)\nE   TypeError: DatabaseManager.add_mention() missing 1 required positional argument: 'mention_data'\n_____________ TestMetricsVisualizer.test_create_temporal_analysis _____________\ntests\\test_ui.py:61: in test_create_temporal_analysis\n    fig = visualizer.create_temporal_analysis(sample_metrics)\nui\\visualization.py:227: in create_temporal_analysis\n    marker_color=self.color_scheme['accent']\nE   KeyError: 'accent'\n_____________ TestMetricsVisualizer.test_malformed_data_handling ______________\ntests\\test_ui.py:165: in test_malformed_data_handling\n    fig = visualizer.create_overview_dashboard(malformed_metrics)\nui\\visualization.py:159: in create_overview_dashboard\n    title_text=f\"Reddit Mentions Dashboard - {overview.get('total_mentions', 0)} Total Mentions\",\nE   AttributeError: 'NoneType' object has no attribute 'get'\n_________________ TestRealTimeMonitor.test_emit_search_failed _________________\ntests\\test_ui.py:333: in test_emit_search_failed\n    assert message['error_message'] == error_message\nE   KeyError: 'error_message'\n_________________ TestRealTimeMonitor.test_emit_mention_found _________________\ntests\\test_ui.py:354: in test_emit_mention_found\n    assert message['mention_data'] == mention_data\nE   KeyError: 'mention_data'\n________________ TestRealTimeMonitor.test_emit_metrics_updated ________________\ntests\\test_ui.py:379: in test_emit_metrics_updated\n    assert message['metrics_summary'] == metrics_summary\nE   KeyError: 'metrics_summary'\n________________ TestRealTimeMonitor.test_get_connection_stats ________________\ntests\\test_ui.py:435: in test_get_connection_stats\n    assert 'server_status' in stats\nE   AssertionError: assert 'server_status' in {'queue_size': 0, 'server_running': False, 'session_subscriptions': {}, 'total_clients': 0}\n============================== warnings summary ===============================\ndatabase\\models.py:10\n  C:\\Users\\Devansh\\Downloads\\intern_application_round1\\database\\models.py:10: MovedIn20Warning: The ``declarative_base()`` function is now available as sqlalchemy.orm.declarative_base(). (deprecated since: 2.0) (Background on SQLAlchemy 2.0 at: https://sqlalche.me/e/b8d9)\n    Base = declarative_base()\n\ntests\\test_analytics.py:35\n  C:\\Users\\Devansh\\Downloads\\intern_application_round1\\tests\\test_analytics.py:35: PytestUnknownMarkWarning: Unknown pytest.mark.smoke - is this a typo?  You can register custom marks to avoid this warning - for details, see https://docs.pytest.org/en/stable/how-to/mark.html\n    @pytest.mark.smoke\n\ntests\\test_analytics.py:36\n  C:\\Users\\Devansh\\Downloads\\intern_application_round1\\tests\\test_analytics.py:36: PytestUnknownMarkWarning: Unknown pytest.mark.unit - is this a typo?  You can register custom marks to avoid this warning - for details, see https://docs.pytest.org/en/stable/how-to/mark.html\n    @pytest.mark.unit\n\ntests\\test_analytics.py:43\n  C:\\Users\\Devansh\\Downloads\\intern_application_round1\\tests\\test_analytics.py:43: PytestUnknownMarkWarning: Unknown pytest.mark.smoke - is this a typo?  You can register custom marks to avoid this warning - for details, see https://docs.pytest.org/en/stable/how-to/mark.html\n    @pytest.mark.smoke\n\ntests\\test_analytics.py:44\n  C:\\Users\\Devansh\\Downloads\\intern_application_round1\\tests\\test_analytics.py:44: PytestUnknownMarkWarning: Unknown pytest.mark.unit - is this a typo?  You can register custom marks to avoid this warning - for details, see https://docs.pytest.org/en/stable/how-to/mark.html\n    @pytest.mark.unit\n\ntests\\test_analytics.py:76\n  C:\\Users\\Devansh\\Downloads\\intern_application_round1\\tests\\test_analytics.py:76: PytestUnknownMarkWarning: Unknown pytest.mark.smoke - is this a typo?  You can register custom marks to avoid this warning - for details, see https://docs.pytest.org/en/stable/how-to/mark.html\n    @pytest.mark.smoke\n\ntests\\test_analytics.py:77\n  C:\\Users\\Devansh\\Downloads\\intern_application_round1\\tests\\test_analytics.py:77: PytestUnknownMarkWarning: Unknown pytest.mark.unit - is this a typo?  You can register custom marks to avoid this warning - for details, see https://docs.pytest.org/en/stable/how-to/mark.html\n    @pytest.mark.unit\n\ntests\\test_analytics.py:109\n  C:\\Users\\Devansh\\Downloads\\intern_application_round1\\tests\\test_analytics.py:109: PytestUnknownMarkWarning: Unknown pytest.mark.unit - is this a typo?  You can register custom marks to avoid this warning - for details, see https://docs.pytest.org/en/stable/how-to/mark.html\n    @pytest.mark.unit\n\ntests\\test_analytics.py:138\n  C:\\Users\\Devansh\\Downloads\\intern_application_round1\\tests\\test_analytics.py:138: PytestUnknownMarkWarning: Unknown pytest.mark.unit - is this a typo?  You can register custom marks to avoid this warning - for details, see https://docs.pytest.org/en/stable/how-to/mark.html\n    @pytest.mark.unit\n\ntests\\test_analytics.py:169\n  C:\\Users\\Devansh\\Downloads\\intern_application_round1\\tests\\test_analytics.py:169: PytestUnknownMarkWarning: Unknown pytest.mark.unit - is this a typo?  You can register custom marks to avoid this warning - for details, see https://docs.pytest.org/en/stable/how-to/mark.html\n    @pytest.mark.unit\n\ntests\\test_analytics.py:196\n  C:\\Users\\Devansh\\Downloads\\intern_application_round1\\tests\\test_analytics.py:196: PytestUnknownMarkWarning: Unknown pytest.mark.unit - is this a typo?  You can register custom marks to avoid this warning - for details, see https://docs.pytest.org/en/stable/how-to/mark.html\n    @pytest.mark.unit\n\ntests\\test_analytics.py:223\n  C:\\Users\\Devansh\\Downloads\\intern_application_round1\\tests\\test_analytics.py:223: PytestUnknownMarkWarning: Unknown pytest.mark.unit - is this a typo?  You can register custom marks to avoid this warning - for details, see https://docs.pytest.org/en/stable/how-to/mark.html\n    @pytest.mark.unit\n\ntests\\test_analytics.py:258\n  C:\\Users\\Devansh\\Downloads\\intern_application_round1\\tests\\test_analytics.py:258: PytestUnknownMarkWarning: Unknown pytest.mark.unit - is this a typo?  You can register custom marks to avoid this warning - for details, see https://docs.pytest.org/en/stable/how-to/mark.html\n    @pytest.mark.unit\n\ntests\\test_analytics.py:291\n  C:\\Users\\Devansh\\Downloads\\intern_application_round1\\tests\\test_analytics.py:291: PytestUnknownMarkWarning: Unknown pytest.mark.unit - is this a typo?  You can register custom marks to avoid this warning - for details, see https://docs.pytest.org/en/stable/how-to/mark.html\n    @pytest.mark.unit\n\ntests\\test_analytics.py:308\n  C:\\Users\\Devansh\\Downloads\\intern_application_round1\\tests\\test_analytics.py:308: PytestUnknownMarkWarning: Unknown pytest.mark.unit - is this a typo?  You can register custom marks to avoid this warning - for details, see https://docs.pytest.org/en/stable/how-to/mark.html\n    @pytest.mark.unit\n\ntests\\test_analytics.py:351\n  C:\\Users\\Devansh\\Downloads\\intern_application_round1\\tests\\test_analytics.py:351: PytestUnknownMarkWarning: Unknown pytest.mark.unit - is this a typo?  You can register custom marks to avoid this warning - for details, see https://docs.pytest.org/en/stable/how-to/mark.html\n    @pytest.mark.unit\n\ntests\\test_analytics.py:359\n  C:\\Users\\Devansh\\Downloads\\intern_application_round1\\tests\\test_analytics.py:359: PytestUnknownMarkWarning: Unknown pytest.mark.unit - is this a typo?  You can register custom marks to avoid this warning - for details, see https://docs.pytest.org/en/stable/how-to/mark.html\n    @pytest.mark.unit\n\ntests\\test_analytics.py:371\n  C:\\Users\\Devansh\\Downloads\\intern_application_round1\\tests\\test_analytics.py:371: PytestUnknownMarkWarning: Unknown pytest.mark.unit - is this a typo?  You can register custom marks to avoid this warning - for details, see https://docs.pytest.org/en/stable/how-to/mark.html\n    @pytest.mark.unit\n\ntests\\test_analytics.py:616\n  C:\\Users\\Devansh\\Downloads\\intern_application_round1\\tests\\test_analytics.py:616: PytestUnknownMarkWarning: Unknown pytest.mark.integration - is this a typo?  You can register custom marks to avoid this warning - for details, see https://docs.pytest.org/en/stable/how-to/mark.html\n    @pytest.mark.integration\n\ntests\\test_analytics.py:642\n  C:\\Users\\Devansh\\Downloads\\intern_application_round1\\tests\\test_analytics.py:642: PytestUnknownMarkWarning: Unknown pytest.mark.integration - is this a typo?  You can register custom marks to avoid this warning - for details, see https://docs.pytest.org/en/stable/how-to/mark.html\n    @pytest.mark.integration\n\ntests\\test_analytics.py:659\n  C:\\Users\\Devansh\\Downloads\\intern_application_round1\\tests\\test_analytics.py:659: PytestUnknownMarkWarning: Unknown pytest.mark.integration - is this a typo?  You can register custom marks to avoid this warning - for details, see https://docs.pytest.org/en/stable/how-to/mark.html\n    @pytest.mark.integration\n\ntests\\test_database.py:16\n  C:\\Users\\Devansh\\Downloads\\intern_application_round1\\tests\\test_database.py:16: PytestUnknownMarkWarning: Unknown pytest.mark.smoke - is this a typo?  You can register custom marks to avoid this warning - for details, see https://docs.pytest.org/en/stable/how-to/mark.html\n    @pytest.mark.smoke\n\ntests\\test_database.py:17\n  C:\\Users\\Devansh\\Downloads\\intern_application_round1\\tests\\test_database.py:17: PytestUnknownMarkWarning: Unknown pytest.mark.unit - is this a typo?  You can register custom marks to avoid this warning - for details, see https://docs.pytest.org/en/stable/how-to/mark.html\n    @pytest.mark.unit\n\ntests\\test_database.py:24\n  C:\\Users\\Devansh\\Downloads\\intern_application_round1\\tests\\test_database.py:24: PytestUnknownMarkWarning: Unknown pytest.mark.smoke - is this a typo?  You can register custom marks to avoid this warning - for details, see https://docs.pytest.org/en/stable/how-to/mark.html\n    @pytest.mark.smoke\n\ntests\\test_database.py:25\n  C:\\Users\\Devansh\\Downloads\\intern_application_round1\\tests\\test_database.py:25: PytestUnknownMarkWarning: Unknown pytest.mark.unit - is this a typo?  You can register custom marks to avoid this warning - for details, see https://docs.pytest.org/en/stable/how-to/mark.html\n    @pytest.mark.unit\n\ntests\\test_database.py:41\n  C:\\Users\\Devansh\\Downloads\\intern_application_round1\\tests\\test_database.py:41: PytestUnknownMarkWarning: Unknown pytest.mark.unit - is this a typo?  You can register custom marks to avoid this warning - for details, see https://docs.pytest.org/en/stable/how-to/mark.html\n    @pytest.mark.unit\n\ntests\\test_database.py:70\n  C:\\Users\\Devansh\\Downloads\\intern_application_round1\\tests\\test_database.py:70: PytestUnknownMarkWarning: Unknown pytest.mark.unit - is this a typo?  You can register custom marks to avoid this warning - for details, see https://docs.pytest.org/en/stable/how-to/mark.html\n    @pytest.mark.unit\n\ntests\\test_database.py:98\n  C:\\Users\\Devansh\\Downloads\\intern_application_round1\\tests\\test_database.py:98: PytestUnknownMarkWarning: Unknown pytest.mark.unit - is this a typo?  You can register custom marks to avoid this warning - for details, see https://docs.pytest.org/en/stable/how-to/mark.html\n    @pytest.mark.unit\n\ntests\\test_database.py:112\n  C:\\Users\\Devansh\\Downloads\\intern_application_round1\\tests\\test_database.py:112: PytestUnknownMarkWarning: Unknown pytest.mark.unit - is this a typo?  You can register custom marks to avoid this warning - for details, see https://docs.pytest.org/en/stable/how-to/mark.html\n    @pytest.mark.unit\n\ntests\\test_database.py:137\n  C:\\Users\\Devansh\\Downloads\\intern_application_round1\\tests\\test_database.py:137: PytestUnknownMarkWarning: Unknown pytest.mark.unit - is this a typo?  You can register custom marks to avoid this warning - for details, see https://docs.pytest.org/en/stable/how-to/mark.html\n    @pytest.mark.unit\n\ntests\\test_database.py:181\n  C:\\Users\\Devansh\\Downloads\\intern_application_round1\\tests\\test_database.py:181: PytestUnknownMarkWarning: Unknown pytest.mark.unit - is this a typo?  You can register custom marks to avoid this warning - for details, see https://docs.pytest.org/en/stable/how-to/mark.html\n    @pytest.mark.unit\n\ntests\\test_database.py:214\n  C:\\Users\\Devansh\\Downloads\\intern_application_round1\\tests\\test_database.py:214: PytestUnknownMarkWarning: Unknown pytest.mark.unit - is this a typo?  You can register custom marks to avoid this warning - for details, see https://docs.pytest.org/en/stable/how-to/mark.html\n    @pytest.mark.unit\n\ntests\\test_database.py:246\n  C:\\Users\\Devansh\\Downloads\\intern_application_round1\\tests\\test_database.py:246: PytestUnknownMarkWarning: Unknown pytest.mark.unit - is this a typo?  You can register custom marks to avoid this warning - for details, see https://docs.pytest.org/en/stable/how-to/mark.html\n    @pytest.mark.unit\n\ntests\\test_database.py:277\n  C:\\Users\\Devansh\\Downloads\\intern_application_round1\\tests\\test_database.py:277: PytestUnknownMarkWarning: Unknown pytest.mark.unit - is this a typo?  You can register custom marks to avoid this warning - for details, see https://docs.pytest.org/en/stable/how-to/mark.html\n    @pytest.mark.unit\n\ntests\\test_database.py:299\n  C:\\Users\\Devansh\\Downloads\\intern_application_round1\\tests\\test_database.py:299: PytestUnknownMarkWarning: Unknown pytest.mark.unit - is this a typo?  You can register custom marks to avoid this warning - for details, see https://docs.pytest.org/en/stable/how-to/mark.html\n    @pytest.mark.unit\n\ntests\\test_database.py:314\n  C:\\Users\\Devansh\\Downloads\\intern_application_round1\\tests\\test_database.py:314: PytestUnknownMarkWarning: Unknown pytest.mark.unit - is this a typo?  You can register custom marks to avoid this warning - for details, see https://docs.pytest.org/en/stable/how-to/mark.html\n    @pytest.mark.unit\n\ntests\\test_database.py:334\n  C:\\Users\\Devansh\\Downloads\\intern_application_round1\\tests\\test_database.py:334: PytestUnknownMarkWarning: Unknown pytest.mark.unit - is this a typo?  You can register custom marks to avoid this warning - for details, see https://docs.pytest.org/en/stable/how-to/mark.html\n    @pytest.mark.unit\n\ntests\\test_database.py:360\n  C:\\Users\\Devansh\\Downloads\\intern_application_round1\\tests\\test_database.py:360: PytestUnknownMarkWarning: Unknown pytest.mark.unit - is this a typo?  You can register custom marks to avoid this warning - for details, see https://docs.pytest.org/en/stable/how-to/mark.html\n    @pytest.mark.unit\n\ntests\\test_database.py:397\n  C:\\Users\\Devansh\\Downloads\\intern_application_round1\\tests\\test_database.py:397: PytestUnknownMarkWarning: Unknown pytest.mark.unit - is this a typo?  You can register custom marks to avoid this warning - for details, see https://docs.pytest.org/en/stable/how-to/mark.html\n    @pytest.mark.unit\n\ntests\\test_database.py:412\n  C:\\Users\\Devansh\\Downloads\\intern_application_round1\\tests\\test_database.py:412: PytestUnknownMarkWarning: Unknown pytest.mark.unit - is this a typo?  You can register custom marks to avoid this warning - for details, see https://docs.pytest.org/en/stable/how-to/mark.html\n    @pytest.mark.unit\n\ntests\\test_database.py:441\n  C:\\Users\\Devansh\\Downloads\\intern_application_round1\\tests\\test_database.py:441: PytestUnknownMarkWarning: Unknown pytest.mark.unit - is this a typo?  You can register custom marks to avoid this warning - for details, see https://docs.pytest.org/en/stable/how-to/mark.html\n    @pytest.mark.unit\n\ntests\\test_database.py:472\n  C:\\Users\\Devansh\\Downloads\\intern_application_round1\\tests\\test_database.py:472: PytestUnknownMarkWarning: Unknown pytest.mark.unit - is this a typo?  You can register custom marks to avoid this warning - for details, see https://docs.pytest.org/en/stable/how-to/mark.html\n    @pytest.mark.unit\n\ntests\\test_integration.py:42\n  C:\\Users\\Devansh\\Downloads\\intern_application_round1\\tests\\test_integration.py:42: PytestUnknownMarkWarning: Unknown pytest.mark.integration - is this a typo?  You can register custom marks to avoid this warning - for details, see https://docs.pytest.org/en/stable/how-to/mark.html\n    @pytest.mark.integration\n\ntests\\test_integration.py:89\n  C:\\Users\\Devansh\\Downloads\\intern_application_round1\\tests\\test_integration.py:89: PytestUnknownMarkWarning: Unknown pytest.mark.integration - is this a typo?  You can register custom marks to avoid this warning - for details, see https://docs.pytest.org/en/stable/how-to/mark.html\n    @pytest.mark.integration\n\ntests\\test_integration.py:112\n  C:\\Users\\Devansh\\Downloads\\intern_application_round1\\tests\\test_integration.py:112: PytestUnknownMarkWarning: Unknown pytest.mark.integration - is this a typo?  You can register custom marks to avoid this warning - for details, see https://docs.pytest.org/en/stable/how-to/mark.html\n    @pytest.mark.integration\n\ntests\\test_integration.py:144\n  C:\\Users\\Devansh\\Downloads\\intern_application_round1\\tests\\test_integration.py:144: PytestUnknownMarkWarning: Unknown pytest.mark.integration - is this a typo?  You can register custom marks to avoid this warning - for details, see https://docs.pytest.org/en/stable/how-to/mark.html\n    @pytest.mark.integration\n\ntests\\test_integration.py:167\n  C:\\Users\\Devansh\\Downloads\\intern_application_round1\\tests\\test_integration.py:167: PytestUnknownMarkWarning: Unknown pytest.mark.integration - is this a typo?  You can register custom marks to avoid this warning - for details, see https://docs.pytest.org/en/stable/how-to/mark.html\n    @pytest.mark.integration\n\ntests\\test_integration.py:204\n  C:\\Users\\Devansh\\Downloads\\intern_application_round1\\tests\\test_integration.py:204: PytestUnknownMarkWarning: Unknown pytest.mark.integration - is this a typo?  You can register custom marks to avoid this warning - for details, see https://docs.pytest.org/en/stable/how-to/mark.html\n    @pytest.mark.integration\n\ntests\\test_integration.py:255\n  C:\\Users\\Devansh\\Downloads\\intern_application_round1\\tests\\test_integration.py:255: PytestUnknownMarkWarning: Unknown pytest.mark.integration - is this a typo?  You can register custom marks to avoid this warning - for details, see https://docs.pytest.org/en/stable/how-to/mark.html\n    @pytest.mark.integration\n\ntests\\test_integration.py:265\n  C:\\Users\\Devansh\\Downloads\\intern_application_round1\\tests\\test_integration.py:265: PytestUnknownMarkWarning: Unknown pytest.mark.integration - is this a typo?  You can register custom marks to avoid this warning - for details, see https://docs.pytest.org/en/stable/how-to/mark.html\n    @pytest.mark.integration\n\ntests\\test_integration.py:284\n  C:\\Users\\Devansh\\Downloads\\intern_application_round1\\tests\\test_integration.py:284: PytestUnknownMarkWarning: Unknown pytest.mark.integration - is this a typo?  You can register custom marks to avoid this warning - for details, see https://docs.pytest.org/en/stable/how-to/mark.html\n    @pytest.mark.integration\n\ntests\\test_integration.py:308\n  C:\\Users\\Devansh\\Downloads\\intern_application_round1\\tests\\test_integration.py:308: PytestUnknownMarkWarning: Unknown pytest.mark.integration - is this a typo?  You can register custom marks to avoid this warning - for details, see https://docs.pytest.org/en/stable/how-to/mark.html\n    @pytest.mark.integration\n\ntests\\test_integration.py:325\n  C:\\Users\\Devansh\\Downloads\\intern_application_round1\\tests\\test_integration.py:325: PytestUnknownMarkWarning: Unknown pytest.mark.integration - is this a typo?  You can register custom marks to avoid this warning - for details, see https://docs.pytest.org/en/stable/how-to/mark.html\n    @pytest.mark.integration\n\ntests\\test_integration.py:348\n  C:\\Users\\Devansh\\Downloads\\intern_application_round1\\tests\\test_integration.py:348: PytestUnknownMarkWarning: Unknown pytest.mark.integration - is this a typo?  You can register custom marks to avoid this warning - for details, see https://docs.pytest.org/en/stable/how-to/mark.html\n    @pytest.mark.integration\n\ntests\\test_integration.py:368\n  C:\\Users\\Devansh\\Downloads\\intern_application_round1\\tests\\test_integration.py:368: PytestUnknownMarkWarning: Unknown pytest.mark.integration - is this a typo?  You can register custom marks to avoid this warning - for details, see https://docs.pytest.org/en/stable/how-to/mark.html\n    @pytest.mark.integration\n\ntests\\test_integration.py:392\n  C:\\Users\\Devansh\\Downloads\\intern_application_round1\\tests\\test_integration.py:392: PytestUnknownMarkWarning: Unknown pytest.mark.integration - is this a typo?  You can register custom marks to avoid this warning - for details, see https://docs.pytest.org/en/stable/how-to/mark.html\n    @pytest.mark.integration\n\ntests\\test_integration.py:424\n  C:\\Users\\Devansh\\Downloads\\intern_application_round1\\tests\\test_integration.py:424: PytestUnknownMarkWarning: Unknown pytest.mark.integration - is this a typo?  You can register custom marks to avoid this warning - for details, see https://docs.pytest.org/en/stable/how-to/mark.html\n    @pytest.mark.integration\n\ntests\\test_integration.py:449\n  C:\\Users\\Devansh\\Downloads\\intern_application_round1\\tests\\test_integration.py:449: PytestUnknownMarkWarning: Unknown pytest.mark.integration - is this a typo?  You can register custom marks to avoid this warning - for details, see https://docs.pytest.org/en/stable/how-to/mark.html\n    @pytest.mark.integration\n\ntests\\test_performance.py:24\n  C:\\Users\\Devansh\\Downloads\\intern_application_round1\\tests\\test_performance.py:24: PytestUnknownMarkWarning: Unknown pytest.mark.performance - is this a typo?  You can register custom marks to avoid this warning - for details, see https://docs.pytest.org/en/stable/how-to/mark.html\n    @pytest.mark.performance\n\ntests\\test_performance.py:61\n  C:\\Users\\Devansh\\Downloads\\intern_application_round1\\tests\\test_performance.py:61: PytestUnknownMarkWarning: Unknown pytest.mark.performance - is this a typo?  You can register custom marks to avoid this warning - for details, see https://docs.pytest.org/en/stable/how-to/mark.html\n    @pytest.mark.performance\n\ntests\\test_performance.py:89\n  C:\\Users\\Devansh\\Downloads\\intern_application_round1\\tests\\test_performance.py:89: PytestUnknownMarkWarning: Unknown pytest.mark.performance - is this a typo?  You can register custom marks to avoid this warning - for details, see https://docs.pytest.org/en/stable/how-to/mark.html\n    @pytest.mark.performance\n\ntests\\test_performance.py:137\n  C:\\Users\\Devansh\\Downloads\\intern_application_round1\\tests\\test_performance.py:137: PytestUnknownMarkWarning: Unknown pytest.mark.performance - is this a typo?  You can register custom marks to avoid this warning - for details, see https://docs.pytest.org/en/stable/how-to/mark.html\n    @pytest.mark.performance\n\ntests\\test_performance.py:165\n  C:\\Users\\Devansh\\Downloads\\intern_application_round1\\tests\\test_performance.py:165: PytestUnknownMarkWarning: Unknown pytest.mark.performance - is this a typo?  You can register custom marks to avoid this warning - for details, see https://docs.pytest.org/en/stable/how-to/mark.html\n    @pytest.mark.performance\n\ntests\\test_performance.py:198\n  C:\\Users\\Devansh\\Downloads\\intern_application_round1\\tests\\test_performance.py:198: PytestUnknownMarkWarning: Unknown pytest.mark.performance - is this a typo?  You can register custom marks to avoid this warning - for details, see https://docs.pytest.org/en/stable/how-to/mark.html\n    @pytest.mark.performance\n\ntests\\test_performance.py:232\n  C:\\Users\\Devansh\\Downloads\\intern_application_round1\\tests\\test_performance.py:232: PytestUnknownMarkWarning: Unknown pytest.mark.performance - is this a typo?  You can register custom marks to avoid this warning - for details, see https://docs.pytest.org/en/stable/how-to/mark.html\n    @pytest.mark.performance\n\ntests\\test_performance.py:278\n  C:\\Users\\Devansh\\Downloads\\intern_application_round1\\tests\\test_performance.py:278: PytestUnknownMarkWarning: Unknown pytest.mark.performance - is this a typo?  You can register custom marks to avoid this warning - for details, see https://docs.pytest.org/en/stable/how-to/mark.html\n    @pytest.mark.performance\n\ntests\\test_performance.py:328\n  C:\\Users\\Devansh\\Downloads\\intern_application_round1\\tests\\test_performance.py:328: PytestUnknownMarkWarning: Unknown pytest.mark.performance - is this a typo?  You can register custom marks to avoid this warning - for details, see https://docs.pytest.org/en/stable/how-to/mark.html\n    @pytest.mark.performance\n\ntests\\test_performance.py:355\n  C:\\Users\\Devansh\\Downloads\\intern_application_round1\\tests\\test_performance.py:355: PytestUnknownMarkWarning: Unknown pytest.mark.performance - is this a typo?  You can register custom marks to avoid this warning - for details, see https://docs.pytest.org/en/stable/how-to/mark.html\n    @pytest.mark.performance\n\ntests\\test_performance.py:386\n  C:\\Users\\Devansh\\Downloads\\intern_application_round1\\tests\\test_performance.py:386: PytestUnknownMarkWarning: Unknown pytest.mark.performance - is this a typo?  You can register custom marks to avoid this warning - for details, see https://docs.pytest.org/en/stable/how-to/mark.html\n    @pytest.mark.performance\n\ntests\\test_performance.py:420\n  C:\\Users\\Devansh\\Downloads\\intern_application_round1\\tests\\test_performance.py:420: PytestUnknownMarkWarning: Unknown pytest.mark.performance - is this a typo?  You can register custom marks to avoid this warning - for details, see https://docs.pytest.org/en/stable/how-to/mark.html\n    @pytest.mark.performance\n\ntests\\test_runner.py:19\n  C:\\Users\\Devansh\\Downloads\\intern_application_round1\\tests\\test_runner.py:19: PytestCollectionWarning: cannot collect test class 'TestRunner' because it has a __init__ constructor (from: tests/test_runner.py)\n    class TestRunner:\n\ntests\\test_scraper.py:20\n  C:\\Users\\Devansh\\Downloads\\intern_application_round1\\tests\\test_scraper.py:20: PytestUnknownMarkWarning: Unknown pytest.mark.smoke - is this a typo?  You can register custom marks to avoid this warning - for details, see https://docs.pytest.org/en/stable/how-to/mark.html\n    @pytest.mark.smoke\n\ntests\\test_scraper.py:21\n  C:\\Users\\Devansh\\Downloads\\intern_application_round1\\tests\\test_scraper.py:21: PytestUnknownMarkWarning: Unknown pytest.mark.unit - is this a typo?  You can register custom marks to avoid this warning - for details, see https://docs.pytest.org/en/stable/how-to/mark.html\n    @pytest.mark.unit\n\ntests\\test_scraper.py:30\n  C:\\Users\\Devansh\\Downloads\\intern_application_round1\\tests\\test_scraper.py:30: PytestUnknownMarkWarning: Unknown pytest.mark.smoke - is this a typo?  You can register custom marks to avoid this warning - for details, see https://docs.pytest.org/en/stable/how-to/mark.html\n    @pytest.mark.smoke\n\ntests\\test_scraper.py:31\n  C:\\Users\\Devansh\\Downloads\\intern_application_round1\\tests\\test_scraper.py:31: PytestUnknownMarkWarning: Unknown pytest.mark.unit - is this a typo?  You can register custom marks to avoid this warning - for details, see https://docs.pytest.org/en/stable/how-to/mark.html\n    @pytest.mark.unit\n\ntests\\test_scraper.py:93\n  C:\\Users\\Devansh\\Downloads\\intern_application_round1\\tests\\test_scraper.py:93: PytestUnknownMarkWarning: Unknown pytest.mark.unit - is this a typo?  You can register custom marks to avoid this warning - for details, see https://docs.pytest.org/en/stable/how-to/mark.html\n    @pytest.mark.unit\n\ntests\\test_scraper.py:489\n  C:\\Users\\Devansh\\Downloads\\intern_application_round1\\tests\\test_scraper.py:489: PytestUnknownMarkWarning: Unknown pytest.mark.unit - is this a typo?  You can register custom marks to avoid this warning - for details, see https://docs.pytest.org/en/stable/how-to/mark.html\n    @pytest.mark.unit\n\ntests\\test_scraper.py:500\n  C:\\Users\\Devansh\\Downloads\\intern_application_round1\\tests\\test_scraper.py:500: PytestUnknownMarkWarning: Unknown pytest.mark.unit - is this a typo?  You can register custom marks to avoid this warning - for details, see https://docs.pytest.org/en/stable/how-to/mark.html\n    @pytest.mark.unit\n\ntests\\test_scraper.py:515\n  C:\\Users\\Devansh\\Downloads\\intern_application_round1\\tests\\test_scraper.py:515: PytestUnknownMarkWarning: Unknown pytest.mark.unit - is this a typo?  You can register custom marks to avoid this warning - for details, see https://docs.pytest.org/en/stable/how-to/mark.html\n    @pytest.mark.unit\n\ntests\\test_scraper.py:531\n  C:\\Users\\Devansh\\Downloads\\intern_application_round1\\tests\\test_scraper.py:531: PytestUnknownMarkWarning: Unknown pytest.mark.unit - is this a typo?  You can register custom marks to avoid this warning - for details, see https://docs.pytest.org/en/stable/how-to/mark.html\n    @pytest.mark.unit\n\ntests\\test_scraper.py:567\n  C:\\Users\\Devansh\\Downloads\\intern_application_round1\\tests\\test_scraper.py:567: PytestUnknownMarkWarning: Unknown pytest.mark.unit - is this a typo?  You can register custom marks to avoid this warning - for details, see https://docs.pytest.org/en/stable/how-to/mark.html\n    @pytest.mark.unit\n\ntests\\test_scraper.py:581\n  C:\\Users\\Devansh\\Downloads\\intern_application_round1\\tests\\test_scraper.py:581: PytestUnknownMarkWarning: Unknown pytest.mark.unit - is this a typo?  You can register custom marks to avoid this warning - for details, see https://docs.pytest.org/en/stable/how-to/mark.html\n    @pytest.mark.unit\n\ntests\\test_security.py:19\n  C:\\Users\\Devansh\\Downloads\\intern_application_round1\\tests\\test_security.py:19: PytestUnknownMarkWarning: Unknown pytest.mark.security - is this a typo?  You can register custom marks to avoid this warning - for details, see https://docs.pytest.org/en/stable/how-to/mark.html\n    @pytest.mark.security\n\ntests\\test_security.py:46\n  C:\\Users\\Devansh\\Downloads\\intern_application_round1\\tests\\test_security.py:46: PytestUnknownMarkWarning: Unknown pytest.mark.security - is this a typo?  You can register custom marks to avoid this warning - for details, see https://docs.pytest.org/en/stable/how-to/mark.html\n    @pytest.mark.security\n\ntests\\test_security.py:81\n  C:\\Users\\Devansh\\Downloads\\intern_application_round1\\tests\\test_security.py:81: PytestUnknownMarkWarning: Unknown pytest.mark.security - is this a typo?  You can register custom marks to avoid this warning - for details, see https://docs.pytest.org/en/stable/how-to/mark.html\n    @pytest.mark.security\n\ntests\\test_security.py:109\n  C:\\Users\\Devansh\\Downloads\\intern_application_round1\\tests\\test_security.py:109: PytestUnknownMarkWarning: Unknown pytest.mark.security - is this a typo?  You can register custom marks to avoid this warning - for details, see https://docs.pytest.org/en/stable/how-to/mark.html\n    @pytest.mark.security\n\ntests\\test_security.py:144\n  C:\\Users\\Devansh\\Downloads\\intern_application_round1\\tests\\test_security.py:144: PytestUnknownMarkWarning: Unknown pytest.mark.security - is this a typo?  You can register custom marks to avoid this warning - for details, see https://docs.pytest.org/en/stable/how-to/mark.html\n    @pytest.mark.security\n\ntests\\test_security.py:170\n  C:\\Users\\Devansh\\Downloads\\intern_application_round1\\tests\\test_security.py:170: PytestUnknownMarkWarning: Unknown pytest.mark.security - is this a typo?  You can register custom marks to avoid this warning - for details, see https://docs.pytest.org/en/stable/how-to/mark.html\n    @pytest.mark.security\n\ntests\\test_security.py:202\n  C:\\Users\\Devansh\\Downloads\\intern_application_round1\\tests\\test_security.py:202: PytestUnknownMarkWarning: Unknown pytest.mark.security - is this a typo?  You can register custom marks to avoid this warning - for details, see https://docs.pytest.org/en/stable/how-to/mark.html\n    @pytest.mark.security\n\ntests\\test_security.py:222\n  C:\\Users\\Devansh\\Downloads\\intern_application_round1\\tests\\test_security.py:222: PytestUnknownMarkWarning: Unknown pytest.mark.security - is this a typo?  You can register custom marks to avoid this warning - for details, see https://docs.pytest.org/en/stable/how-to/mark.html\n    @pytest.mark.security\n\ntests\\test_security.py:249\n  C:\\Users\\Devansh\\Downloads\\intern_application_round1\\tests\\test_security.py:249: PytestUnknownMarkWarning: Unknown pytest.mark.security - is this a typo?  You can register custom marks to avoid this warning - for details, see https://docs.pytest.org/en/stable/how-to/mark.html\n    @pytest.mark.security\n\ntests\\test_security.py:271\n  C:\\Users\\Devansh\\Downloads\\intern_application_round1\\tests\\test_security.py:271: PytestUnknownMarkWarning: Unknown pytest.mark.security - is this a typo?  You can register custom marks to avoid this warning - for details, see https://docs.pytest.org/en/stable/how-to/mark.html\n    @pytest.mark.security\n\ntests\\test_security.py:290\n  C:\\Users\\Devansh\\Downloads\\intern_application_round1\\tests\\test_security.py:290: PytestUnknownMarkWarning: Unknown pytest.mark.security - is this a typo?  You can register custom marks to avoid this warning - for details, see https://docs.pytest.org/en/stable/how-to/mark.html\n    @pytest.mark.security\n\ntests\\test_ui.py:19\n  C:\\Users\\Devansh\\Downloads\\intern_application_round1\\tests\\test_ui.py:19: PytestUnknownMarkWarning: Unknown pytest.mark.unit - is this a typo?  You can register custom marks to avoid this warning - for details, see https://docs.pytest.org/en/stable/how-to/mark.html\n    @pytest.mark.unit\n\ntests\\test_ui.py:27\n  C:\\Users\\Devansh\\Downloads\\intern_application_round1\\tests\\test_ui.py:27: PytestUnknownMarkWarning: Unknown pytest.mark.unit - is this a typo?  You can register custom marks to avoid this warning - for details, see https://docs.pytest.org/en/stable/how-to/mark.html\n    @pytest.mark.unit\n\ntests\\test_ui.py:45\n  C:\\Users\\Devansh\\Downloads\\intern_application_round1\\tests\\test_ui.py:45: PytestUnknownMarkWarning: Unknown pytest.mark.unit - is this a typo?  You can register custom marks to avoid this warning - for details, see https://docs.pytest.org/en/stable/how-to/mark.html\n    @pytest.mark.unit\n\ntests\\test_ui.py:66\n  C:\\Users\\Devansh\\Downloads\\intern_application_round1\\tests\\test_ui.py:66: PytestUnknownMarkWarning: Unknown pytest.mark.unit - is this a typo?  You can register custom marks to avoid this warning - for details, see https://docs.pytest.org/en/stable/how-to/mark.html\n    @pytest.mark.unit\n\ntests\\test_ui.py:87\n  C:\\Users\\Devansh\\Downloads\\intern_application_round1\\tests\\test_ui.py:87: PytestUnknownMarkWarning: Unknown pytest.mark.unit - is this a typo?  You can register custom marks to avoid this warning - for details, see https://docs.pytest.org/en/stable/how-to/mark.html\n    @pytest.mark.unit\n\ntests\\test_ui.py:107\n  C:\\Users\\Devansh\\Downloads\\intern_application_round1\\tests\\test_ui.py:107: PytestUnknownMarkWarning: Unknown pytest.mark.unit - is this a typo?  You can register custom marks to avoid this warning - for details, see https://docs.pytest.org/en/stable/how-to/mark.html\n    @pytest.mark.unit\n\ntests\\test_ui.py:125\n  C:\\Users\\Devansh\\Downloads\\intern_application_round1\\tests\\test_ui.py:125: PytestUnknownMarkWarning: Unknown pytest.mark.unit - is this a typo?  You can register custom marks to avoid this warning - for details, see https://docs.pytest.org/en/stable/how-to/mark.html\n    @pytest.mark.unit\n\ntests\\test_ui.py:140\n  C:\\Users\\Devansh\\Downloads\\intern_application_round1\\tests\\test_ui.py:140: PytestUnknownMarkWarning: Unknown pytest.mark.unit - is this a typo?  You can register custom marks to avoid this warning - for details, see https://docs.pytest.org/en/stable/how-to/mark.html\n    @pytest.mark.unit\n\ntests\\test_ui.py:155\n  C:\\Users\\Devansh\\Downloads\\intern_application_round1\\tests\\test_ui.py:155: PytestUnknownMarkWarning: Unknown pytest.mark.unit - is this a typo?  You can register custom marks to avoid this warning - for details, see https://docs.pytest.org/en/stable/how-to/mark.html\n    @pytest.mark.unit\n\ntests\\test_ui.py:168\n  C:\\Users\\Devansh\\Downloads\\intern_application_round1\\tests\\test_ui.py:168: PytestUnknownMarkWarning: Unknown pytest.mark.unit - is this a typo?  You can register custom marks to avoid this warning - for details, see https://docs.pytest.org/en/stable/how-to/mark.html\n    @pytest.mark.unit\n\ntests\\test_ui.py:183\n  C:\\Users\\Devansh\\Downloads\\intern_application_round1\\tests\\test_ui.py:183: PytestUnknownMarkWarning: Unknown pytest.mark.unit - is this a typo?  You can register custom marks to avoid this warning - for details, see https://docs.pytest.org/en/stable/how-to/mark.html\n    @pytest.mark.unit\n\ntests\\test_ui.py:201\n  C:\\Users\\Devansh\\Downloads\\intern_application_round1\\tests\\test_ui.py:201: PytestUnknownMarkWarning: Unknown pytest.mark.unit - is this a typo?  You can register custom marks to avoid this warning - for details, see https://docs.pytest.org/en/stable/how-to/mark.html\n    @pytest.mark.unit\n\ntests\\test_ui.py:220\n  C:\\Users\\Devansh\\Downloads\\intern_application_round1\\tests\\test_ui.py:220: PytestUnknownMarkWarning: Unknown pytest.mark.unit - is this a typo?  You can register custom marks to avoid this warning - for details, see https://docs.pytest.org/en/stable/how-to/mark.html\n    @pytest.mark.unit\n\ntests\\test_ui.py:231\n  C:\\Users\\Devansh\\Downloads\\intern_application_round1\\tests\\test_ui.py:231: PytestUnknownMarkWarning: Unknown pytest.mark.unit - is this a typo?  You can register custom marks to avoid this warning - for details, see https://docs.pytest.org/en/stable/how-to/mark.html\n    @pytest.mark.unit\n\ntests\\test_ui.py:244\n  C:\\Users\\Devansh\\Downloads\\intern_application_round1\\tests\\test_ui.py:244: PytestUnknownMarkWarning: Unknown pytest.mark.unit - is this a typo?  You can register custom marks to avoid this warning - for details, see https://docs.pytest.org/en/stable/how-to/mark.html\n    @pytest.mark.unit\n\ntests\\test_ui.py:267\n  C:\\Users\\Devansh\\Downloads\\intern_application_round1\\tests\\test_ui.py:267: PytestUnknownMarkWarning: Unknown pytest.mark.unit - is this a typo?  You can register custom marks to avoid this warning - for details, see https://docs.pytest.org/en/stable/how-to/mark.html\n    @pytest.mark.unit\n\ntests\\test_ui.py:292\n  C:\\Users\\Devansh\\Downloads\\intern_application_round1\\tests\\test_ui.py:292: PytestUnknownMarkWarning: Unknown pytest.mark.unit - is this a typo?  You can register custom marks to avoid this warning - for details, see https://docs.pytest.org/en/stable/how-to/mark.html\n    @pytest.mark.unit\n\ntests\\test_ui.py:315\n  C:\\Users\\Devansh\\Downloads\\intern_application_round1\\tests\\test_ui.py:315: PytestUnknownMarkWarning: Unknown pytest.mark.unit - is this a typo?  You can register custom marks to avoid this warning - for details, see https://docs.pytest.org/en/stable/how-to/mark.html\n    @pytest.mark.unit\n\ntests\\test_ui.py:336\n  C:\\Users\\Devansh\\Downloads\\intern_application_round1\\tests\\test_ui.py:336: PytestUnknownMarkWarning: Unknown pytest.mark.unit - is this a typo?  You can register custom marks to avoid this warning - for details, see https://docs.pytest.org/en/stable/how-to/mark.html\n    @pytest.mark.unit\n\ntests\\test_ui.py:357\n  C:\\Users\\Devansh\\Downloads\\intern_application_round1\\tests\\test_ui.py:357: PytestUnknownMarkWarning: Unknown pytest.mark.unit - is this a typo?  You can register custom marks to avoid this warning - for details, see https://docs.pytest.org/en/stable/how-to/mark.html\n    @pytest.mark.unit\n\ntests\\test_ui.py:382\n  C:\\Users\\Devansh\\Downloads\\intern_application_round1\\tests\\test_ui.py:382: PytestUnknownMarkWarning: Unknown pytest.mark.unit - is this a typo?  You can register custom marks to avoid this warning - for details, see https://docs.pytest.org/en/stable/how-to/mark.html\n    @pytest.mark.unit\n\ntests\\test_ui.py:403\n  C:\\Users\\Devansh\\Downloads\\intern_application_round1\\tests\\test_ui.py:403: PytestUnknownMarkWarning: Unknown pytest.mark.unit - is this a typo?  You can register custom marks to avoid this warning - for details, see https://docs.pytest.org/en/stable/how-to/mark.html\n    @pytest.mark.unit\n\ntests\\test_ui.py:427\n  C:\\Users\\Devansh\\Downloads\\intern_application_round1\\tests\\test_ui.py:427: PytestUnknownMarkWarning: Unknown pytest.mark.unit - is this a typo?  You can register custom marks to avoid this warning - for details, see https://docs.pytest.org/en/stable/how-to/mark.html\n    @pytest.mark.unit\n\ntests\\test_ui.py:442\n  C:\\Users\\Devansh\\Downloads\\intern_application_round1\\tests\\test_ui.py:442: PytestUnknownMarkWarning: Unknown pytest.mark.unit - is this a typo?  You can register custom marks to avoid this warning - for details, see https://docs.pytest.org/en/stable/how-to/mark.html\n    @pytest.mark.unit\n\ntests\\test_ui.py:454\n  C:\\Users\\Devansh\\Downloads\\intern_application_round1\\tests\\test_ui.py:454: PytestUnknownMarkWarning: Unknown pytest.mark.unit - is this a typo?  You can register custom marks to avoid this warning - for details, see https://docs.pytest.org/en/stable/how-to/mark.html\n    @pytest.mark.unit\n\ntests\\test_ui.py:476\n  C:\\Users\\Devansh\\Downloads\\intern_application_round1\\tests\\test_ui.py:476: PytestUnknownMarkWarning: Unknown pytest.mark.unit - is this a typo?  You can register custom marks to avoid this warning - for details, see https://docs.pytest.org/en/stable/how-to/mark.html\n    @pytest.mark.unit\n\ntests\\test_ui.py:504\n  C:\\Users\\Devansh\\Downloads\\intern_application_round1\\tests\\test_ui.py:504: PytestUnknownMarkWarning: Unknown pytest.mark.unit - is this a typo?  You can register custom marks to avoid this warning - for details, see https://docs.pytest.org/en/stable/how-to/mark.html\n    @pytest.mark.unit\n\ntests\\test_ui.py:530\n  C:\\Users\\Devansh\\Downloads\\intern_application_round1\\tests\\test_ui.py:530: PytestUnknownMarkWarning: Unknown pytest.mark.unit - is this a typo?  You can register custom marks to avoid this warning - for details, see https://docs.pytest.org/en/stable/how-to/mark.html\n    @pytest.mark.unit\n\ntests/test_analytics.py::TestMetricsAnalyzer::test_calculate_basic_metrics\ntests/test_analytics.py::TestMetricsAnalyzer::test_analyze_session_metrics\ntests/test_analytics.py::TestMetricsAnalyzer::test_calculate_temporal_metrics\ntests/test_analytics.py::TestMetricsAnalyzer::test_calculate_subreddit_metrics\ntests/test_analytics.py::TestMetricsAnalyzer::test_calculate_sentiment_metrics\ntests/test_analytics.py::TestMetricsAnalyzer::test_calculate_engagement_metrics\ntests/test_analytics.py::TestMetricsAnalyzer::test_detect_trending_topics\ntests/test_analytics.py::TestMetricsAnalyzer::test_generate_comprehensive_metrics\ntests/test_analytics.py::TestDataValidator::test_validate_mention_valid_data\n  C:\\Users\\Devansh\\Downloads\\intern_application_round1\\tests\\conftest.py:27: DeprecationWarning: datetime.datetime.utcnow() is deprecated and scheduled for removal in a future version. Use timezone-aware objects to represent datetimes in UTC: datetime.datetime.now(datetime.UTC).\n    'created_utc': datetime.utcnow(),\n\ntests/test_analytics.py::TestMetricsAnalyzer::test_calculate_basic_metrics\ntests/test_analytics.py::TestMetricsAnalyzer::test_analyze_session_metrics\ntests/test_analytics.py::TestMetricsAnalyzer::test_calculate_temporal_metrics\ntests/test_analytics.py::TestMetricsAnalyzer::test_calculate_subreddit_metrics\ntests/test_analytics.py::TestMetricsAnalyzer::test_calculate_sentiment_metrics\ntests/test_analytics.py::TestMetricsAnalyzer::test_calculate_engagement_metrics\ntests/test_analytics.py::TestMetricsAnalyzer::test_detect_trending_topics\ntests/test_analytics.py::TestMetricsAnalyzer::test_generate_comprehensive_metrics\ntests/test_analytics.py::TestDataValidator::test_validate_mention_valid_data\n  C:\\Users\\Devansh\\Downloads\\intern_application_round1\\tests\\conftest.py:30: DeprecationWarning: datetime.datetime.utcnow() is deprecated and scheduled for removal in a future version. Use timezone-aware objects to represent datetimes in UTC: datetime.datetime.now(datetime.UTC).\n    'scraped_at': datetime.utcnow()\n\ntests/test_analytics.py::TestMetricsAnalyzer::test_calculate_basic_metrics\ntests/test_analytics.py::TestMetricsAnalyzer::test_analyze_session_metrics\ntests/test_analytics.py::TestMetricsAnalyzer::test_calculate_temporal_metrics\ntests/test_analytics.py::TestMetricsAnalyzer::test_calculate_subreddit_metrics\ntests/test_analytics.py::TestMetricsAnalyzer::test_calculate_sentiment_metrics\ntests/test_analytics.py::TestMetricsAnalyzer::test_calculate_engagement_metrics\ntests/test_analytics.py::TestMetricsAnalyzer::test_detect_trending_topics\ntests/test_analytics.py::TestMetricsAnalyzer::test_generate_comprehensive_metrics\ntests/test_analytics.py::TestMetricsAnalyzer::test_malformed_data_handling\n  C:\\Users\\Devansh\\Downloads\\intern_application_round1\\analytics\\metrics_analyzer.py:88: DeprecationWarning: datetime.datetime.utcnow() is deprecated and scheduled for removal in a future version. Use timezone-aware objects to represent datetimes in UTC: datetime.datetime.now(datetime.UTC).\n    cutoff_date = datetime.utcnow() - timedelta(days=days)\n\ntests/test_analytics.py::TestMetricsAnalyzer::test_calculate_basic_metrics\ntests/test_analytics.py::TestMetricsAnalyzer::test_analyze_session_metrics\ntests/test_analytics.py::TestMetricsAnalyzer::test_calculate_temporal_metrics\ntests/test_analytics.py::TestMetricsAnalyzer::test_calculate_subreddit_metrics\ntests/test_analytics.py::TestMetricsAnalyzer::test_calculate_sentiment_metrics\ntests/test_analytics.py::TestMetricsAnalyzer::test_calculate_engagement_metrics\ntests/test_analytics.py::TestMetricsAnalyzer::test_detect_trending_topics\ntests/test_analytics.py::TestMetricsAnalyzer::test_generate_comprehensive_metrics\ntests/test_analytics.py::TestMetricsAnalyzer::test_malformed_data_handling\n  C:\\Users\\Devansh\\Downloads\\intern_application_round1\\analytics\\metrics_analyzer.py:166: DeprecationWarning: datetime.datetime.utcnow() is deprecated and scheduled for removal in a future version. Use timezone-aware objects to represent datetimes in UTC: datetime.datetime.now(datetime.UTC).\n    start=datetime.utcnow().date() - timedelta(days=days-1),\n\ntests/test_analytics.py::TestMetricsAnalyzer::test_calculate_basic_metrics\ntests/test_analytics.py::TestMetricsAnalyzer::test_analyze_session_metrics\ntests/test_analytics.py::TestMetricsAnalyzer::test_calculate_temporal_metrics\ntests/test_analytics.py::TestMetricsAnalyzer::test_calculate_subreddit_metrics\ntests/test_analytics.py::TestMetricsAnalyzer::test_calculate_sentiment_metrics\ntests/test_analytics.py::TestMetricsAnalyzer::test_calculate_engagement_metrics\ntests/test_analytics.py::TestMetricsAnalyzer::test_detect_trending_topics\ntests/test_analytics.py::TestMetricsAnalyzer::test_generate_comprehensive_metrics\ntests/test_analytics.py::TestMetricsAnalyzer::test_malformed_data_handling\n  C:\\Users\\Devansh\\Downloads\\intern_application_round1\\analytics\\metrics_analyzer.py:167: DeprecationWarning: datetime.datetime.utcnow() is deprecated and scheduled for removal in a future version. Use timezone-aware objects to represent datetimes in UTC: datetime.datetime.now(datetime.UTC).\n    end=datetime.utcnow().date(),\n\ntests/test_analytics.py::TestMetricsAnalyzer::test_calculate_basic_metrics\ntests/test_analytics.py::TestMetricsAnalyzer::test_analyze_session_metrics\ntests/test_analytics.py::TestMetricsAnalyzer::test_calculate_temporal_metrics\ntests/test_analytics.py::TestMetricsAnalyzer::test_calculate_subreddit_metrics\ntests/test_analytics.py::TestMetricsAnalyzer::test_calculate_sentiment_metrics\ntests/test_analytics.py::TestMetricsAnalyzer::test_calculate_engagement_metrics\ntests/test_analytics.py::TestMetricsAnalyzer::test_detect_trending_topics\ntests/test_analytics.py::TestMetricsAnalyzer::test_generate_comprehensive_metrics\n  C:\\Users\\Devansh\\Downloads\\intern_application_round1\\analytics\\metrics_analyzer.py:314: DeprecationWarning: datetime.datetime.utcnow() is deprecated and scheduled for removal in a future version. Use timezone-aware objects to represent datetimes in UTC: datetime.datetime.now(datetime.UTC).\n    now = datetime.utcnow()\n\ntests/test_analytics.py::TestMetricsAnalyzer::test_calculate_temporal_metrics\n  C:\\Users\\Devansh\\Downloads\\intern_application_round1\\tests\\test_analytics.py:118: DeprecationWarning: datetime.datetime.utcnow() is deprecated and scheduled for removal in a future version. Use timezone-aware objects to represent datetimes in UTC: datetime.datetime.now(datetime.UTC).\n    now = datetime.utcnow()\n\ntests/test_analytics.py::TestMetricsAnalyzer::test_malformed_data_handling\n  C:\\Users\\Devansh\\Downloads\\intern_application_round1\\tests\\test_analytics.py:331: DeprecationWarning: datetime.datetime.utcnow() is deprecated and scheduled for removal in a future version. Use timezone-aware objects to represent datetimes in UTC: datetime.datetime.now(datetime.UTC).\n    mock_mention.created_utc = datetime.utcnow()\n\ntests/test_analytics.py::TestMetricsAnalyzer::test_malformed_data_handling\n  C:\\Users\\Devansh\\Downloads\\intern_application_round1\\tests\\test_analytics.py:332: DeprecationWarning: datetime.datetime.utcnow() is deprecated and scheduled for removal in a future version. Use timezone-aware objects to represent datetimes in UTC: datetime.datetime.now(datetime.UTC).\n    mock_mention.scraped_at = datetime.utcnow()\n\ntests/test_analytics.py::TestDataValidator::test_validate_mention_valid_data\ntests/test_analytics.py::TestDataValidator::test_validate_mention_invalid_data\n  C:\\Users\\Devansh\\Downloads\\intern_application_round1\\analytics\\data_validator.py:222: DeprecationWarning: datetime.datetime.utcnow() is deprecated and scheduled for removal in a future version. Use timezone-aware objects to represent datetimes in UTC: datetime.datetime.now(datetime.UTC).\n    'validation_timestamp': datetime.utcnow().isoformat()\n\ntests/test_database.py: 17 warnings\n  C:\\Users\\Devansh\\AppData\\Roaming\\Python\\Python312\\site-packages\\sqlalchemy\\sql\\schema.py:3616: DeprecationWarning: datetime.datetime.utcnow() is deprecated and scheduled for removal in a future version. Use timezone-aware objects to represent datetimes in UTC: datetime.datetime.now(datetime.UTC).\n    return util.wrap_callable(lambda ctx: fn(), fn)  # type: ignore\n\ntests/test_database.py::TestDatabaseManager::test_add_mention\n  C:\\Users\\Devansh\\Downloads\\intern_application_round1\\tests\\test_database.py:58: DeprecationWarning: datetime.datetime.utcnow() is deprecated and scheduled for removal in a future version. Use timezone-aware objects to represent datetimes in UTC: datetime.datetime.now(datetime.UTC).\n    'created_utc': datetime.utcnow(),\n\ntests/test_database.py::TestDatabaseManager::test_get_mentions_by_session\n  C:\\Users\\Devansh\\Downloads\\intern_application_round1\\tests\\test_database.py:86: DeprecationWarning: datetime.datetime.utcnow() is deprecated and scheduled for removal in a future version. Use timezone-aware objects to represent datetimes in UTC: datetime.datetime.now(datetime.UTC).\n    'created_utc': datetime.utcnow()\n\ntests/test_database.py::TestDatabaseManager::test_get_session_statistics\n  C:\\Users\\Devansh\\Downloads\\intern_application_round1\\tests\\test_database.py:129: DeprecationWarning: datetime.datetime.utcnow() is deprecated and scheduled for removal in a future version. Use timezone-aware objects to represent datetimes in UTC: datetime.datetime.now(datetime.UTC).\n    'created_utc': datetime.utcnow()\n\ntests/test_database.py::TestDatabaseManager::test_search_mentions\n  C:\\Users\\Devansh\\Downloads\\intern_application_round1\\tests\\test_database.py:153: DeprecationWarning: datetime.datetime.utcnow() is deprecated and scheduled for removal in a future version. Use timezone-aware objects to represent datetimes in UTC: datetime.datetime.now(datetime.UTC).\n    'created_utc': datetime.utcnow()\n\ntests/test_database.py::TestDatabaseManager::test_search_mentions\n  C:\\Users\\Devansh\\Downloads\\intern_application_round1\\tests\\test_database.py:166: DeprecationWarning: datetime.datetime.utcnow() is deprecated and scheduled for removal in a future version. Use timezone-aware objects to represent datetimes in UTC: datetime.datetime.now(datetime.UTC).\n    'created_utc': datetime.utcnow()\n\ntests/test_database.py::TestDatabaseManager::test_get_trending_subreddits\n  C:\\Users\\Devansh\\Downloads\\intern_application_round1\\tests\\test_database.py:200: DeprecationWarning: datetime.datetime.utcnow() is deprecated and scheduled for removal in a future version. Use timezone-aware objects to represent datetimes in UTC: datetime.datetime.now(datetime.UTC).\n    'created_utc': datetime.utcnow()\n\ntests/test_database.py::TestDatabaseManager::test_get_sentiment_distribution\n  C:\\Users\\Devansh\\Downloads\\intern_application_round1\\tests\\test_database.py:233: DeprecationWarning: datetime.datetime.utcnow() is deprecated and scheduled for removal in a future version. Use timezone-aware objects to represent datetimes in UTC: datetime.datetime.now(datetime.UTC).\n    'created_utc': datetime.utcnow(),\n\ntests/test_database.py::TestDatabaseManager::test_get_time_series_data\n  C:\\Users\\Devansh\\Downloads\\intern_application_round1\\tests\\test_database.py:252: DeprecationWarning: datetime.datetime.utcnow() is deprecated and scheduled for removal in a future version. Use timezone-aware objects to represent datetimes in UTC: datetime.datetime.now(datetime.UTC).\n    base_time = datetime.utcnow()\n\ntests/test_database.py::TestDatabaseManager::test_cleanup_old_sessions\n  C:\\Users\\Devansh\\Downloads\\intern_application_round1\\tests\\test_database.py:286: DeprecationWarning: datetime.datetime.utcnow() is deprecated and scheduled for removal in a future version. Use timezone-aware objects to represent datetimes in UTC: datetime.datetime.now(datetime.UTC).\n    old_session.created_at = datetime.utcnow() - timedelta(days=30)\n\ntests/test_database.py::TestDatabaseManager::test_database_error_handling\n  C:\\Users\\Devansh\\Downloads\\intern_application_round1\\tests\\test_database.py:326: DeprecationWarning: datetime.datetime.utcnow() is deprecated and scheduled for removal in a future version. Use timezone-aware objects to represent datetimes in UTC: datetime.datetime.now(datetime.UTC).\n    'created_utc': datetime.utcnow()\n\ntests/test_database.py::TestDatabaseManager::test_duplicate_mention_handling\n  C:\\Users\\Devansh\\Downloads\\intern_application_round1\\tests\\test_database.py:349: DeprecationWarning: datetime.datetime.utcnow() is deprecated and scheduled for removal in a future version. Use timezone-aware objects to represent datetimes in UTC: datetime.datetime.now(datetime.UTC).\n    'created_utc': datetime.utcnow()\n\ntests/test_database.py::TestDatabaseManager::test_database_backup_restore\n  C:\\Users\\Devansh\\Downloads\\intern_application_round1\\tests\\test_database.py:376: DeprecationWarning: datetime.datetime.utcnow() is deprecated and scheduled for removal in a future version. Use timezone-aware objects to represent datetimes in UTC: datetime.datetime.now(datetime.UTC).\n    'created_utc': datetime.utcnow(),\n\ntests/test_database.py::TestSearchSession::test_search_session_relationships\n  C:\\Users\\Devansh\\Downloads\\intern_application_round1\\tests\\test_database.py:428: DeprecationWarning: datetime.datetime.utcnow() is deprecated and scheduled for removal in a future version. Use timezone-aware objects to represent datetimes in UTC: datetime.datetime.now(datetime.UTC).\n    'created_utc': datetime.utcnow()\n\ntests/test_database.py::TestRedditMention::test_reddit_mention_creation\n  C:\\Users\\Devansh\\Downloads\\intern_application_round1\\tests\\test_database.py:458: DeprecationWarning: datetime.datetime.utcnow() is deprecated and scheduled for removal in a future version. Use timezone-aware objects to represent datetimes in UTC: datetime.datetime.now(datetime.UTC).\n    created_utc=datetime.utcnow(),\n\ntests/test_database.py::TestRedditMention::test_reddit_mention_validation\n  C:\\Users\\Devansh\\Downloads\\intern_application_round1\\tests\\test_database.py:482: DeprecationWarning: datetime.datetime.utcnow() is deprecated and scheduled for removal in a future version. Use timezone-aware objects to represent datetimes in UTC: datetime.datetime.now(datetime.UTC).\n    created_utc=datetime.utcnow()\n\ntests/test_scraper.py::TestScrapingConfiguration::test_validate_mention_data\n  C:\\Users\\Devansh\\Downloads\\intern_application_round1\\tests\\test_scraper.py:543: DeprecationWarning: datetime.datetime.utcnow() is deprecated and scheduled for removal in a future version. Use timezone-aware objects to represent datetimes in UTC: datetime.datetime.now(datetime.UTC).\n    'created_utc': datetime.utcnow(),\n\ntests/test_ui.py: 11 warnings\n  C:\\Users\\Devansh\\Downloads\\intern_application_round1\\tests\\conftest.py:27: DeprecationWarning:\n  \n  datetime.datetime.utcnow() is deprecated and scheduled for removal in a future version. Use timezone-aware objects to represent datetimes in UTC: datetime.datetime.now(datetime.UTC).\n\ntests/test_ui.py: 11 warnings\n  C:\\Users\\Devansh\\Downloads\\intern_application_round1\\tests\\conftest.py:30: DeprecationWarning:\n  \n  datetime.datetime.utcnow() is deprecated and scheduled for removal in a future version. Use timezone-aware objects to represent datetimes in UTC: datetime.datetime.now(datetime.UTC).\n\ntests/test_ui.py::TestRealTimeMonitor::test_emit_search_started\ntests/test_ui.py::TestRealTimeMonitor::test_multiple_event_emissions\ntests/test_ui.py::TestRealTimeMonitor::test_event_message_structure\n  C:\\Users\\Devansh\\Downloads\\intern_application_round1\\ui\\realtime_monitor.py:188: DeprecationWarning:\n  \n  datetime.datetime.utcnow() is deprecated and scheduled for removal in a future version. Use timezone-aware objects to represent datetimes in UTC: datetime.datetime.now(datetime.UTC).\n\ntests/test_ui.py::TestRealTimeMonitor::test_emit_search_progress\ntests/test_ui.py::TestRealTimeMonitor::test_progress_callback_execution\ntests/test_ui.py::TestRealTimeMonitor::test_progress_callback_with_mention\ntests/test_ui.py::TestRealTimeMonitor::test_multiple_event_emissions\ntests/test_ui.py::TestRealTimeMonitor::test_multiple_event_emissions\ntests/test_ui.py::TestRealTimeMonitor::test_event_message_structure\n  C:\\Users\\Devansh\\Downloads\\intern_application_round1\\ui\\realtime_monitor.py:199: DeprecationWarning:\n  \n  datetime.datetime.utcnow() is deprecated and scheduled for removal in a future version. Use timezone-aware objects to represent datetimes in UTC: datetime.datetime.now(datetime.UTC).\n\ntests/test_ui.py::TestRealTimeMonitor::test_emit_search_completed\ntests/test_ui.py::TestRealTimeMonitor::test_multiple_event_emissions\ntests/test_ui.py::TestRealTimeMonitor::test_event_message_structure\n  C:\\Users\\Devansh\\Downloads\\intern_application_round1\\ui\\realtime_monitor.py:209: DeprecationWarning:\n  \n  datetime.datetime.utcnow() is deprecated and scheduled for removal in a future version. Use timezone-aware objects to represent datetimes in UTC: datetime.datetime.now(datetime.UTC).\n\ntests/test_ui.py::TestRealTimeMonitor::test_emit_search_failed\ntests/test_ui.py::TestRealTimeMonitor::test_event_message_structure\n  C:\\Users\\Devansh\\Downloads\\intern_application_round1\\ui\\realtime_monitor.py:218: DeprecationWarning:\n  \n  datetime.datetime.utcnow() is deprecated and scheduled for removal in a future version. Use timezone-aware objects to represent datetimes in UTC: datetime.datetime.now(datetime.UTC).\n\ntests/test_ui.py::TestRealTimeMonitor::test_emit_mention_found\ntests/test_ui.py::TestRealTimeMonitor::test_progress_callback_with_mention\ntests/test_ui.py::TestRealTimeMonitor::test_event_message_structure\n  C:\\Users\\Devansh\\Downloads\\intern_application_round1\\ui\\realtime_monitor.py:238: DeprecationWarning:\n  \n  datetime.datetime.utcnow() is deprecated and scheduled for removal in a future version. Use timezone-aware objects to represent datetimes in UTC: datetime.datetime.now(datetime.UTC).\n\ntests/test_ui.py::TestRealTimeMonitor::test_emit_metrics_updated\ntests/test_ui.py::TestRealTimeMonitor::test_event_message_structure\n  C:\\Users\\Devansh\\Downloads\\intern_application_round1\\ui\\realtime_monitor.py:247: DeprecationWarning:\n  \n  datetime.datetime.utcnow() is deprecated and scheduled for removal in a future version. Use timezone-aware objects to represent datetimes in UTC: datetime.datetime.now(datetime.UTC).\n\ntests/test_ui.py::TestRealTimeMonitor::test_emit_cache_hit\ntests/test_ui.py::TestRealTimeMonitor::test_event_message_structure\n  C:\\Users\\Devansh\\Downloads\\intern_application_round1\\ui\\realtime_monitor.py:256: DeprecationWarning:\n  \n  datetime.datetime.utcnow() is deprecated and scheduled for removal in a future version. Use timezone-aware objects to represent datetimes in UTC: datetime.datetime.now(datetime.UTC).\n\ntests/test_ui.py::TestRealTimeMonitor::test_emit_system_status\ntests/test_ui.py::TestRealTimeMonitor::test_event_message_structure\n  C:\\Users\\Devansh\\Downloads\\intern_application_round1\\ui\\realtime_monitor.py:264: DeprecationWarning:\n  \n  datetime.datetime.utcnow() is deprecated and scheduled for removal in a future version. Use timezone-aware objects to represent datetimes in UTC: datetime.datetime.now(datetime.UTC).\n\ntests/test_ui.py::TestRealTimeMonitor::test_progress_callback_initialization\ntests/test_ui.py::TestRealTimeMonitor::test_progress_callback_execution\ntests/test_ui.py::TestRealTimeMonitor::test_progress_callback_with_mention\n  C:\\Users\\Devansh\\Downloads\\intern_application_round1\\ui\\realtime_monitor.py:307: DeprecationWarning:\n  \n  datetime.datetime.utcnow() is deprecated and scheduled for removal in a future version. Use timezone-aware objects to represent datetimes in UTC: datetime.datetime.now(datetime.UTC).\n\n-- Docs: https://docs.pytest.org/en/stable/how-to/capture-warnings.html\n=========================== short test summary info ===========================\nFAILED tests/test_database.py::TestDatabaseManager::test_add_mention - TypeEr...\nFAILED tests/test_database.py::TestDatabaseManager::test_get_mentions_by_session\nFAILED tests/test_database.py::TestDatabaseManager::test_get_session_statistics\nFAILED tests/test_database.py::TestDatabaseManager::test_search_mentions - Ty...\nFAILED tests/test_database.py::TestDatabaseManager::test_get_trending_subreddits\nFAILED tests/test_database.py::TestDatabaseManager::test_get_sentiment_distribution\nFAILED tests/test_database.py::TestDatabaseManager::test_get_time_series_data\nFAILED tests/test_database.py::TestDatabaseManager::test_duplicate_mention_handling\nFAILED tests/test_database.py::TestDatabaseManager::test_database_backup_restore\nFAILED tests/test_database.py::TestSearchSession::test_search_session_relationships\nFAILED tests/test_ui.py::TestMetricsVisualizer::test_create_temporal_analysis\nFAILED tests/test_ui.py::TestMetricsVisualizer::test_malformed_data_handling\nFAILED tests/test_ui.py::TestRealTimeMonitor::test_emit_search_failed - KeyEr...\nFAILED tests/test_ui.py::TestRealTimeMonitor::test_emit_mention_found - KeyEr...\nFAILED tests/test_ui.py::TestRealTimeMonitor::test_emit_metrics_updated - Key...\nFAILED tests/test_ui.py::TestRealTimeMonitor::test_get_connection_stats - Ass...\n========= 16 failed, 54 passed, 94 deselected, 260 warnings in 4.69s ==========\n",
      "stderr": "",
      "critical": true
    },
    "integration": {
      "category": "integration",
      "description": "Integration Tests - Component Interaction",
      "success": false,
      "execution_time": 11.733579635620117,
      "statistics": {
        "total": 25,
        "passed": 6,
        "failed": 10,
        "skipped": 0,
        "errors": 9
      },
      "stdout": "============================= test session starts =============================\nplatform win32 -- Python 3.12.1, pytest-8.3.5, pluggy-1.5.0 -- C:\\Program Files\\Python312\\python.exe\ncachedir: .pytest_cache\nmetadata: {'Python': '3.12.1', 'Platform': 'Windows-10-10.0.19045-SP0', 'Packages': {'pytest': '8.3.5', 'pluggy': '1.5.0'}, 'Plugins': {'anyio': '4.8.0', 'asyncio': '0.21.1', 'cov': '4.1.0', 'html': '4.1.1', 'metadata': '3.1.1', 'xdist': '3.7.0'}}\nrootdir: C:\\Users\\Devansh\\Downloads\\intern_application_round1\nconfigfile: pytest.ini\nplugins: anyio-4.8.0, asyncio-0.21.1, cov-4.1.0, html-4.1.1, metadata-3.1.1, xdist-3.7.0\nasyncio: mode=Mode.STRICT\ncollecting ... collected 164 items / 145 deselected / 19 selected\n\ntests/test_analytics.py::TestAnalyticsIntegration::test_full_analytics_pipeline FAILED [  5%]\ntests/test_analytics.py::TestAnalyticsIntegration::test_analytics_with_empty_data PASSED [ 10%]\ntests/test_analytics.py::TestAnalyticsIntegration::test_analytics_performance FAILED [ 15%]\ntests/test_integration.py::TestSystemIntegration::test_complete_workflow FAILED [ 21%]\ntests/test_integration.py::TestSystemIntegration::test_complete_workflow ERROR [ 21%]\ntests/test_integration.py::TestSystemIntegration::test_async_workflow FAILED [ 26%]\ntests/test_integration.py::TestSystemIntegration::test_async_workflow ERROR [ 26%]\ntests/test_integration.py::TestSystemIntegration::test_error_propagation PASSED [ 31%]\ntests/test_integration.py::TestSystemIntegration::test_error_propagation ERROR [ 31%]\ntests/test_integration.py::TestSystemIntegration::test_data_consistency FAILED [ 36%]\ntests/test_integration.py::TestSystemIntegration::test_data_consistency ERROR [ 36%]\ntests/test_integration.py::TestSystemIntegration::test_concurrent_access FAILED [ 42%]\ntests/test_integration.py::TestSystemIntegration::test_concurrent_access ERROR [ 42%]\ntests/test_integration.py::TestSystemIntegration::test_performance_integration FAILED [ 47%]\ntests/test_integration.py::TestSystemIntegration::test_performance_integration ERROR [ 47%]\ntests/test_integration.py::TestAPIIntegration::test_api_health_endpoint PASSED [ 52%]\ntests/test_integration.py::TestAPIIntegration::test_api_search_endpoint FAILED [ 57%]\ntests/test_integration.py::TestAPIIntegration::test_api_error_handling PASSED [ 63%]\ntests/test_integration.py::TestCacheIntegration::test_cache_integration_basic FAILED [ 68%]\ntests/test_integration.py::TestCacheIntegration::test_cache_performance_impact FAILED [ 73%]\ntests/test_integration.py::TestConfigurationIntegration::test_environment_configuration PASSED [ 78%]\ntests/test_integration.py::TestConfigurationIntegration::test_feature_flags PASSED [ 84%]\ntests/test_integration.py::TestEndToEndWorkflow::test_complete_user_workflow ERROR [ 89%]\ntests/test_integration.py::TestEndToEndWorkflow::test_error_recovery_workflow ERROR [ 94%]\ntests/test_integration.py::TestEndToEndWorkflow::test_scalability_workflow ERROR [100%]\n\n=================================== ERRORS ====================================\n______ ERROR at teardown of TestSystemIntegration.test_complete_workflow ______\ntests\\conftest.py:55: in temp_database\n    shutil.rmtree(temp_dir)\nC:\\Program Files\\Python312\\Lib\\shutil.py:808: in rmtree\n    return _rmtree_unsafe(path, onexc)\nC:\\Program Files\\Python312\\Lib\\shutil.py:636: in _rmtree_unsafe\n    onexc(os.unlink, fullname, err)\nC:\\Program Files\\Python312\\Lib\\shutil.py:634: in _rmtree_unsafe\n    os.unlink(fullname)\nE   PermissionError: [WinError 32] The process cannot access the file because it is being used by another process: 'C:\\\\Users\\\\Devansh\\\\AppData\\\\Local\\\\Temp\\\\tmpbbp4ppji\\\\test.db'\n_______ ERROR at teardown of TestSystemIntegration.test_async_workflow ________\ntests\\conftest.py:55: in temp_database\n    shutil.rmtree(temp_dir)\nC:\\Program Files\\Python312\\Lib\\shutil.py:808: in rmtree\n    return _rmtree_unsafe(path, onexc)\nC:\\Program Files\\Python312\\Lib\\shutil.py:636: in _rmtree_unsafe\n    onexc(os.unlink, fullname, err)\nC:\\Program Files\\Python312\\Lib\\shutil.py:634: in _rmtree_unsafe\n    os.unlink(fullname)\nE   PermissionError: [WinError 32] The process cannot access the file because it is being used by another process: 'C:\\\\Users\\\\Devansh\\\\AppData\\\\Local\\\\Temp\\\\tmpimaqt192\\\\test.db'\n______ ERROR at teardown of TestSystemIntegration.test_error_propagation ______\ntests\\conftest.py:55: in temp_database\n    shutil.rmtree(temp_dir)\nC:\\Program Files\\Python312\\Lib\\shutil.py:808: in rmtree\n    return _rmtree_unsafe(path, onexc)\nC:\\Program Files\\Python312\\Lib\\shutil.py:636: in _rmtree_unsafe\n    onexc(os.unlink, fullname, err)\nC:\\Program Files\\Python312\\Lib\\shutil.py:634: in _rmtree_unsafe\n    os.unlink(fullname)\nE   PermissionError: [WinError 32] The process cannot access the file because it is being used by another process: 'C:\\\\Users\\\\Devansh\\\\AppData\\\\Local\\\\Temp\\\\tmpz7qay89e\\\\test.db'\n______ ERROR at teardown of TestSystemIntegration.test_data_consistency _______\ntests\\conftest.py:55: in temp_database\n    shutil.rmtree(temp_dir)\nC:\\Program Files\\Python312\\Lib\\shutil.py:808: in rmtree\n    return _rmtree_unsafe(path, onexc)\nC:\\Program Files\\Python312\\Lib\\shutil.py:636: in _rmtree_unsafe\n    onexc(os.unlink, fullname, err)\nC:\\Program Files\\Python312\\Lib\\shutil.py:634: in _rmtree_unsafe\n    os.unlink(fullname)\nE   PermissionError: [WinError 32] The process cannot access the file because it is being used by another process: 'C:\\\\Users\\\\Devansh\\\\AppData\\\\Local\\\\Temp\\\\tmplfyz0lfz\\\\test.db'\n______ ERROR at teardown of TestSystemIntegration.test_concurrent_access ______\ntests\\conftest.py:55: in temp_database\n    shutil.rmtree(temp_dir)\nC:\\Program Files\\Python312\\Lib\\shutil.py:808: in rmtree\n    return _rmtree_unsafe(path, onexc)\nC:\\Program Files\\Python312\\Lib\\shutil.py:636: in _rmtree_unsafe\n    onexc(os.unlink, fullname, err)\nC:\\Program Files\\Python312\\Lib\\shutil.py:634: in _rmtree_unsafe\n    os.unlink(fullname)\nE   PermissionError: [WinError 32] The process cannot access the file because it is being used by another process: 'C:\\\\Users\\\\Devansh\\\\AppData\\\\Local\\\\Temp\\\\tmplpy4zh_5\\\\test.db'\n___ ERROR at teardown of TestSystemIntegration.test_performance_integration ___\ntests\\conftest.py:55: in temp_database\n    shutil.rmtree(temp_dir)\nC:\\Program Files\\Python312\\Lib\\shutil.py:808: in rmtree\n    return _rmtree_unsafe(path, onexc)\nC:\\Program Files\\Python312\\Lib\\shutil.py:636: in _rmtree_unsafe\n    onexc(os.unlink, fullname, err)\nC:\\Program Files\\Python312\\Lib\\shutil.py:634: in _rmtree_unsafe\n    os.unlink(fullname)\nE   PermissionError: [WinError 32] The process cannot access the file because it is being used by another process: 'C:\\\\Users\\\\Devansh\\\\AppData\\\\Local\\\\Temp\\\\tmppybqj_5c\\\\test.db'\n_____ ERROR at setup of TestEndToEndWorkflow.test_complete_user_workflow ______\nfile C:\\Users\\Devansh\\Downloads\\intern_application_round1\\tests\\test_integration.py, line 391\n      @pytest.mark.asyncio\n      @pytest.mark.integration\n      async def test_complete_user_workflow(self, integrated_system, sample_mentions_list):\n          \"\"\"Test complete user workflow from API to visualization.\"\"\"\n          system = integrated_system\n\n          # Step 1: User initiates search (mocked)\n          search_term = \"end_to_end_test\"\n          session_id = system['db_manager'].create_search_session(search_term)\n\n          # Step 2: System scrapes data (simulated)\n          for mention in sample_mentions_list[:5]:  # Use subset for speed\n              mention_copy = mention.copy()\n              mention_copy['reddit_id'] = f\"e2e_{mention['reddit_id']}\"\n              system['db_manager'].add_mention(session_id, mention_copy)\n\n          # Step 3: System processes and analyzes data\n          mentions = system['db_manager'].get_mentions_by_session(session_id)\n          assert len(mentions) == 5\n\n          # Step 4: Generate analytics\n          analytics = system['metrics_analyzer'].analyze_session_metrics(session_id)\n          assert isinstance(analytics, dict)\n          assert 'overview' in analytics\n\n          # Step 5: User views results (mocked visualization)\n          with patch.object(system['visualizer'], 'create_overview_dashboard') as mock_viz:\n              mock_viz.return_value = {'charts': 'generated'}\n              dashboard = system['visualizer'].create_overview_dashboard(analytics)\n              assert dashboard is not None\n\n          print(f\"End-to-end workflow completed for session {session_id}\")\nE       fixture 'integrated_system' not found\n>       available fixtures: anyio_backend, anyio_backend_name, anyio_backend_options, api_client, async_test_client, cache, cache_manager, capfd, capfdbinary, caplog, capsys, capsysbinary, cov, data_validator, db_manager, doctest_namespace, event_loop, extra, extras, include_metadata_in_junit_xml, metadata, metrics_analyzer, mock_browser_context, mock_playwright_page, mock_redis, mock_requests, mock_textblob, monitor, monkeypatch, no_cover, performance_monitor, pytestconfig, record_property, record_testsuite_property, record_xml_attribute, recwarn, sample_mention_data, sample_mentions_list, scraper, sentiment_analyzer, temp_database, test_config, test_data_generator, testrun_uid, tmp_path, tmp_path_factory, tmpdir, tmpdir_factory, unused_tcp_port, unused_tcp_port_factory, unused_udp_port, unused_udp_port_factory, visualizer, worker_id\n>       use 'pytest --fixtures [testpath]' for help on them.\n\nC:\\Users\\Devansh\\Downloads\\intern_application_round1\\tests\\test_integration.py:391\n_____ ERROR at setup of TestEndToEndWorkflow.test_error_recovery_workflow _____\nfile C:\\Users\\Devansh\\Downloads\\intern_application_round1\\tests\\test_integration.py, line 424\n      @pytest.mark.integration\n      def test_error_recovery_workflow(self, integrated_system):\nE       fixture 'integrated_system' not found\n>       available fixtures: anyio_backend, anyio_backend_name, anyio_backend_options, api_client, async_test_client, cache, cache_manager, capfd, capfdbinary, caplog, capsys, capsysbinary, cov, data_validator, db_manager, doctest_namespace, event_loop, extra, extras, include_metadata_in_junit_xml, metadata, metrics_analyzer, mock_browser_context, mock_playwright_page, mock_redis, mock_requests, mock_textblob, monitor, monkeypatch, no_cover, performance_monitor, pytestconfig, record_property, record_testsuite_property, record_xml_attribute, recwarn, sample_mention_data, sample_mentions_list, scraper, sentiment_analyzer, temp_database, test_config, test_data_generator, testrun_uid, tmp_path, tmp_path_factory, tmpdir, tmpdir_factory, unused_tcp_port, unused_tcp_port_factory, unused_udp_port, unused_udp_port_factory, visualizer, worker_id\n>       use 'pytest --fixtures [testpath]' for help on them.\n\nC:\\Users\\Devansh\\Downloads\\intern_application_round1\\tests\\test_integration.py:424\n______ ERROR at setup of TestEndToEndWorkflow.test_scalability_workflow _______\nfile C:\\Users\\Devansh\\Downloads\\intern_application_round1\\tests\\test_integration.py, line 449\n      @pytest.mark.integration\n      def test_scalability_workflow(self, integrated_system, performance_monitor):\nE       fixture 'integrated_system' not found\n>       available fixtures: anyio_backend, anyio_backend_name, anyio_backend_options, api_client, async_test_client, cache, cache_manager, capfd, capfdbinary, caplog, capsys, capsysbinary, cov, data_validator, db_manager, doctest_namespace, event_loop, extra, extras, include_metadata_in_junit_xml, metadata, metrics_analyzer, mock_browser_context, mock_playwright_page, mock_redis, mock_requests, mock_textblob, monitor, monkeypatch, no_cover, performance_monitor, pytestconfig, record_property, record_testsuite_property, record_xml_attribute, recwarn, sample_mention_data, sample_mentions_list, scraper, sentiment_analyzer, temp_database, test_config, test_data_generator, testrun_uid, tmp_path, tmp_path_factory, tmpdir, tmpdir_factory, unused_tcp_port, unused_tcp_port_factory, unused_udp_port, unused_udp_port_factory, visualizer, worker_id\n>       use 'pytest --fixtures [testpath]' for help on them.\n\nC:\\Users\\Devansh\\Downloads\\intern_application_round1\\tests\\test_integration.py:449\n================================== FAILURES ===================================\n____________ TestAnalyticsIntegration.test_full_analytics_pipeline ____________\ntests\\test_analytics.py:627: in test_full_analytics_pipeline\n    db_manager.add_mention(session_id, mention)\ndatabase\\models.py:131: in add_mention\n    mention = RedditMention(**mention_data)\n<string>:4: in __init__\n    ???\n..\\..\\AppData\\Roaming\\Python\\Python312\\site-packages\\sqlalchemy\\orm\\state.py:571: in _initialize_instance\n    with util.safe_reraise():\n..\\..\\AppData\\Roaming\\Python\\Python312\\site-packages\\sqlalchemy\\util\\langhelpers.py:146: in __exit__\n    raise exc_value.with_traceback(exc_tb)\n..\\..\\AppData\\Roaming\\Python\\Python312\\site-packages\\sqlalchemy\\orm\\state.py:569: in _initialize_instance\n    manager.original_init(*mixed[1:], **kwargs)\n..\\..\\AppData\\Roaming\\Python\\Python312\\site-packages\\sqlalchemy\\orm\\decl_base.py:2175: in _declarative_constructor\n    raise TypeError(\nE   TypeError: '_quality_score' is an invalid keyword argument for RedditMention\n_____________ TestAnalyticsIntegration.test_analytics_performance _____________\ntests\\test_analytics.py:693: in test_analytics_performance\n    db_manager.add_mention(session_id, mention)\ndatabase\\models.py:131: in add_mention\n    mention = RedditMention(**mention_data)\n<string>:4: in __init__\n    ???\n..\\..\\AppData\\Roaming\\Python\\Python312\\site-packages\\sqlalchemy\\orm\\state.py:571: in _initialize_instance\n    with util.safe_reraise():\n..\\..\\AppData\\Roaming\\Python\\Python312\\site-packages\\sqlalchemy\\util\\langhelpers.py:146: in __exit__\n    raise exc_value.with_traceback(exc_tb)\n..\\..\\AppData\\Roaming\\Python\\Python312\\site-packages\\sqlalchemy\\orm\\state.py:569: in _initialize_instance\n    manager.original_init(*mixed[1:], **kwargs)\n..\\..\\AppData\\Roaming\\Python\\Python312\\site-packages\\sqlalchemy\\orm\\decl_base.py:2175: in _declarative_constructor\n    raise TypeError(\nE   TypeError: '_quality_score' is an invalid keyword argument for RedditMention\n________________ TestSystemIntegration.test_complete_workflow _________________\n..\\..\\AppData\\Roaming\\Python\\Python312\\site-packages\\sqlalchemy\\engine\\base.py:1964: in _exec_single_context\n    self.dialect.do_execute(\n..\\..\\AppData\\Roaming\\Python\\Python312\\site-packages\\sqlalchemy\\engine\\default.py:942: in do_execute\n    cursor.execute(statement, parameters)\nE   sqlite3.IntegrityError: NOT NULL constraint failed: reddit_mentions.post_type\n\nThe above exception was the direct cause of the following exception:\ntests\\test_integration.py:53: in test_complete_workflow\n    mention_id = system['db_manager'].add_mention(session_id, mention)\ndatabase\\models.py:133: in add_mention\n    db.commit()\n..\\..\\AppData\\Roaming\\Python\\Python312\\site-packages\\sqlalchemy\\orm\\session.py:2032: in commit\n    trans.commit(_to_root=True)\n<string>:2: in commit\n    ???\n..\\..\\AppData\\Roaming\\Python\\Python312\\site-packages\\sqlalchemy\\orm\\state_changes.py:139: in _go\n    ret_value = fn(self, *arg, **kw)\n..\\..\\AppData\\Roaming\\Python\\Python312\\site-packages\\sqlalchemy\\orm\\session.py:1313: in commit\n    self._prepare_impl()\n<string>:2: in _prepare_impl\n    ???\n..\\..\\AppData\\Roaming\\Python\\Python312\\site-packages\\sqlalchemy\\orm\\state_changes.py:139: in _go\n    ret_value = fn(self, *arg, **kw)\n..\\..\\AppData\\Roaming\\Python\\Python312\\site-packages\\sqlalchemy\\orm\\session.py:1288: in _prepare_impl\n    self.session.flush()\n..\\..\\AppData\\Roaming\\Python\\Python312\\site-packages\\sqlalchemy\\orm\\session.py:4353: in flush\n    self._flush(objects)\n..\\..\\AppData\\Roaming\\Python\\Python312\\site-packages\\sqlalchemy\\orm\\session.py:4488: in _flush\n    with util.safe_reraise():\n..\\..\\AppData\\Roaming\\Python\\Python312\\site-packages\\sqlalchemy\\util\\langhelpers.py:146: in __exit__\n    raise exc_value.with_traceback(exc_tb)\n..\\..\\AppData\\Roaming\\Python\\Python312\\site-packages\\sqlalchemy\\orm\\session.py:4449: in _flush\n    flush_context.execute()\n..\\..\\AppData\\Roaming\\Python\\Python312\\site-packages\\sqlalchemy\\orm\\unitofwork.py:466: in execute\n    rec.execute(self)\n..\\..\\AppData\\Roaming\\Python\\Python312\\site-packages\\sqlalchemy\\orm\\unitofwork.py:642: in execute\n    util.preloaded.orm_persistence.save_obj(\n..\\..\\AppData\\Roaming\\Python\\Python312\\site-packages\\sqlalchemy\\orm\\persistence.py:93: in save_obj\n    _emit_insert_statements(\n..\\..\\AppData\\Roaming\\Python\\Python312\\site-packages\\sqlalchemy\\orm\\persistence.py:1233: in _emit_insert_statements\n    result = connection.execute(\n..\\..\\AppData\\Roaming\\Python\\Python312\\site-packages\\sqlalchemy\\engine\\base.py:1416: in execute\n    return meth(\n..\\..\\AppData\\Roaming\\Python\\Python312\\site-packages\\sqlalchemy\\sql\\elements.py:523: in _execute_on_connection\n    return connection._execute_clauseelement(\n..\\..\\AppData\\Roaming\\Python\\Python312\\site-packages\\sqlalchemy\\engine\\base.py:1638: in _execute_clauseelement\n    ret = self._execute_context(\n..\\..\\AppData\\Roaming\\Python\\Python312\\site-packages\\sqlalchemy\\engine\\base.py:1843: in _execute_context\n    return self._exec_single_context(\n..\\..\\AppData\\Roaming\\Python\\Python312\\site-packages\\sqlalchemy\\engine\\base.py:1983: in _exec_single_context\n    self._handle_dbapi_exception(\n..\\..\\AppData\\Roaming\\Python\\Python312\\site-packages\\sqlalchemy\\engine\\base.py:2352: in _handle_dbapi_exception\n    raise sqlalchemy_exception.with_traceback(exc_info[2]) from e\n..\\..\\AppData\\Roaming\\Python\\Python312\\site-packages\\sqlalchemy\\engine\\base.py:1964: in _exec_single_context\n    self.dialect.do_execute(\n..\\..\\AppData\\Roaming\\Python\\Python312\\site-packages\\sqlalchemy\\engine\\default.py:942: in do_execute\n    cursor.execute(statement, parameters)\nE   sqlalchemy.exc.IntegrityError: (sqlite3.IntegrityError) NOT NULL constraint failed: reddit_mentions.post_type\nE   [SQL: INSERT INTO reddit_mentions (session_id, reddit_id, post_type, title, content, author, subreddit, url, score, num_comments, upvote_ratio, created_utc, scraped_at, sentiment_score, relevance_score) VALUES (?, ?, ?, ?, ?, ?, ?, ?, ?, ?, ?, ?, ?, ?, ?)]\nE   [parameters: (1, 'test0', None, 'Test post 0 about OpenAI', 'This is a test post discussing OpenAI technology and its impact.', 'test_user', 'technology', 'https://reddit.com/r/technology/comments/test123', 10, 15, None, '2025-05-29 01:32:53.227466', '2025-05-29 01:32:53.227466', -0.5, 0.8)]\nE   (Background on this error at: https://sqlalche.me/e/20/gkpj)\n__________________ TestSystemIntegration.test_async_workflow __________________\n..\\..\\AppData\\Roaming\\Python\\Python312\\site-packages\\sqlalchemy\\engine\\base.py:1964: in _exec_single_context\n    self.dialect.do_execute(\n..\\..\\AppData\\Roaming\\Python\\Python312\\site-packages\\sqlalchemy\\engine\\default.py:942: in do_execute\n    cursor.execute(statement, parameters)\nE   sqlite3.IntegrityError: NOT NULL constraint failed: reddit_mentions.post_type\n\nThe above exception was the direct cause of the following exception:\ntests\\test_integration.py:107: in test_async_workflow\n    system['db_manager'].add_mention(session_id, mention)\ndatabase\\models.py:133: in add_mention\n    db.commit()\n..\\..\\AppData\\Roaming\\Python\\Python312\\site-packages\\sqlalchemy\\orm\\session.py:2032: in commit\n    trans.commit(_to_root=True)\n<string>:2: in commit\n    ???\n..\\..\\AppData\\Roaming\\Python\\Python312\\site-packages\\sqlalchemy\\orm\\state_changes.py:139: in _go\n    ret_value = fn(self, *arg, **kw)\n..\\..\\AppData\\Roaming\\Python\\Python312\\site-packages\\sqlalchemy\\orm\\session.py:1313: in commit\n    self._prepare_impl()\n<string>:2: in _prepare_impl\n    ???\n..\\..\\AppData\\Roaming\\Python\\Python312\\site-packages\\sqlalchemy\\orm\\state_changes.py:139: in _go\n    ret_value = fn(self, *arg, **kw)\n..\\..\\AppData\\Roaming\\Python\\Python312\\site-packages\\sqlalchemy\\orm\\session.py:1288: in _prepare_impl\n    self.session.flush()\n..\\..\\AppData\\Roaming\\Python\\Python312\\site-packages\\sqlalchemy\\orm\\session.py:4353: in flush\n    self._flush(objects)\n..\\..\\AppData\\Roaming\\Python\\Python312\\site-packages\\sqlalchemy\\orm\\session.py:4488: in _flush\n    with util.safe_reraise():\n..\\..\\AppData\\Roaming\\Python\\Python312\\site-packages\\sqlalchemy\\util\\langhelpers.py:146: in __exit__\n    raise exc_value.with_traceback(exc_tb)\n..\\..\\AppData\\Roaming\\Python\\Python312\\site-packages\\sqlalchemy\\orm\\session.py:4449: in _flush\n    flush_context.execute()\n..\\..\\AppData\\Roaming\\Python\\Python312\\site-packages\\sqlalchemy\\orm\\unitofwork.py:466: in execute\n    rec.execute(self)\n..\\..\\AppData\\Roaming\\Python\\Python312\\site-packages\\sqlalchemy\\orm\\unitofwork.py:642: in execute\n    util.preloaded.orm_persistence.save_obj(\n..\\..\\AppData\\Roaming\\Python\\Python312\\site-packages\\sqlalchemy\\orm\\persistence.py:93: in save_obj\n    _emit_insert_statements(\n..\\..\\AppData\\Roaming\\Python\\Python312\\site-packages\\sqlalchemy\\orm\\persistence.py:1233: in _emit_insert_statements\n    result = connection.execute(\n..\\..\\AppData\\Roaming\\Python\\Python312\\site-packages\\sqlalchemy\\engine\\base.py:1416: in execute\n    return meth(\n..\\..\\AppData\\Roaming\\Python\\Python312\\site-packages\\sqlalchemy\\sql\\elements.py:523: in _execute_on_connection\n    return connection._execute_clauseelement(\n..\\..\\AppData\\Roaming\\Python\\Python312\\site-packages\\sqlalchemy\\engine\\base.py:1638: in _execute_clauseelement\n    ret = self._execute_context(\n..\\..\\AppData\\Roaming\\Python\\Python312\\site-packages\\sqlalchemy\\engine\\base.py:1843: in _execute_context\n    return self._exec_single_context(\n..\\..\\AppData\\Roaming\\Python\\Python312\\site-packages\\sqlalchemy\\engine\\base.py:1983: in _exec_single_context\n    self._handle_dbapi_exception(\n..\\..\\AppData\\Roaming\\Python\\Python312\\site-packages\\sqlalchemy\\engine\\base.py:2352: in _handle_dbapi_exception\n    raise sqlalchemy_exception.with_traceback(exc_info[2]) from e\n..\\..\\AppData\\Roaming\\Python\\Python312\\site-packages\\sqlalchemy\\engine\\base.py:1964: in _exec_single_context\n    self.dialect.do_execute(\n..\\..\\AppData\\Roaming\\Python\\Python312\\site-packages\\sqlalchemy\\engine\\default.py:942: in do_execute\n    cursor.execute(statement, parameters)\nE   sqlalchemy.exc.IntegrityError: (sqlite3.IntegrityError) NOT NULL constraint failed: reddit_mentions.post_type\nE   [SQL: INSERT INTO reddit_mentions (session_id, reddit_id, post_type, title, content, author, subreddit, url, score, num_comments, upvote_ratio, created_utc, scraped_at, sentiment_score, relevance_score) VALUES (?, ?, ?, ?, ?, ?, ?, ?, ?, ?, ?, ?, ?, ?, ?)]\nE   [parameters: (1, 'test0', None, 'Test post 0 about OpenAI', 'This is a test post discussing OpenAI technology and its impact.', 'test_user', 'technology', 'https://reddit.com/r/technology/comments/test123', 10, 15, None, '2025-05-29 01:32:53.458468', '2025-05-29 01:32:53.458468', -0.5, 0.8)]\nE   (Background on this error at: https://sqlalche.me/e/20/gkpj)\n_________________ TestSystemIntegration.test_data_consistency _________________\n..\\..\\AppData\\Roaming\\Python\\Python312\\site-packages\\sqlalchemy\\engine\\base.py:1964: in _exec_single_context\n    self.dialect.do_execute(\n..\\..\\AppData\\Roaming\\Python\\Python312\\site-packages\\sqlalchemy\\engine\\default.py:942: in do_execute\n    cursor.execute(statement, parameters)\nE   sqlite3.IntegrityError: NOT NULL constraint failed: reddit_mentions.post_type\n\nThe above exception was the direct cause of the following exception:\ntests\\test_integration.py:153: in test_data_consistency\n    system['db_manager'].add_mention(session_id, mention)\ndatabase\\models.py:133: in add_mention\n    db.commit()\n..\\..\\AppData\\Roaming\\Python\\Python312\\site-packages\\sqlalchemy\\orm\\session.py:2032: in commit\n    trans.commit(_to_root=True)\n<string>:2: in commit\n    ???\n..\\..\\AppData\\Roaming\\Python\\Python312\\site-packages\\sqlalchemy\\orm\\state_changes.py:139: in _go\n    ret_value = fn(self, *arg, **kw)\n..\\..\\AppData\\Roaming\\Python\\Python312\\site-packages\\sqlalchemy\\orm\\session.py:1313: in commit\n    self._prepare_impl()\n<string>:2: in _prepare_impl\n    ???\n..\\..\\AppData\\Roaming\\Python\\Python312\\site-packages\\sqlalchemy\\orm\\state_changes.py:139: in _go\n    ret_value = fn(self, *arg, **kw)\n..\\..\\AppData\\Roaming\\Python\\Python312\\site-packages\\sqlalchemy\\orm\\session.py:1288: in _prepare_impl\n    self.session.flush()\n..\\..\\AppData\\Roaming\\Python\\Python312\\site-packages\\sqlalchemy\\orm\\session.py:4353: in flush\n    self._flush(objects)\n..\\..\\AppData\\Roaming\\Python\\Python312\\site-packages\\sqlalchemy\\orm\\session.py:4488: in _flush\n    with util.safe_reraise():\n..\\..\\AppData\\Roaming\\Python\\Python312\\site-packages\\sqlalchemy\\util\\langhelpers.py:146: in __exit__\n    raise exc_value.with_traceback(exc_tb)\n..\\..\\AppData\\Roaming\\Python\\Python312\\site-packages\\sqlalchemy\\orm\\session.py:4449: in _flush\n    flush_context.execute()\n..\\..\\AppData\\Roaming\\Python\\Python312\\site-packages\\sqlalchemy\\orm\\unitofwork.py:466: in execute\n    rec.execute(self)\n..\\..\\AppData\\Roaming\\Python\\Python312\\site-packages\\sqlalchemy\\orm\\unitofwork.py:642: in execute\n    util.preloaded.orm_persistence.save_obj(\n..\\..\\AppData\\Roaming\\Python\\Python312\\site-packages\\sqlalchemy\\orm\\persistence.py:93: in save_obj\n    _emit_insert_statements(\n..\\..\\AppData\\Roaming\\Python\\Python312\\site-packages\\sqlalchemy\\orm\\persistence.py:1233: in _emit_insert_statements\n    result = connection.execute(\n..\\..\\AppData\\Roaming\\Python\\Python312\\site-packages\\sqlalchemy\\engine\\base.py:1416: in execute\n    return meth(\n..\\..\\AppData\\Roaming\\Python\\Python312\\site-packages\\sqlalchemy\\sql\\elements.py:523: in _execute_on_connection\n    return connection._execute_clauseelement(\n..\\..\\AppData\\Roaming\\Python\\Python312\\site-packages\\sqlalchemy\\engine\\base.py:1638: in _execute_clauseelement\n    ret = self._execute_context(\n..\\..\\AppData\\Roaming\\Python\\Python312\\site-packages\\sqlalchemy\\engine\\base.py:1843: in _execute_context\n    return self._exec_single_context(\n..\\..\\AppData\\Roaming\\Python\\Python312\\site-packages\\sqlalchemy\\engine\\base.py:1983: in _exec_single_context\n    self._handle_dbapi_exception(\n..\\..\\AppData\\Roaming\\Python\\Python312\\site-packages\\sqlalchemy\\engine\\base.py:2352: in _handle_dbapi_exception\n    raise sqlalchemy_exception.with_traceback(exc_info[2]) from e\n..\\..\\AppData\\Roaming\\Python\\Python312\\site-packages\\sqlalchemy\\engine\\base.py:1964: in _exec_single_context\n    self.dialect.do_execute(\n..\\..\\AppData\\Roaming\\Python\\Python312\\site-packages\\sqlalchemy\\engine\\default.py:942: in do_execute\n    cursor.execute(statement, parameters)\nE   sqlalchemy.exc.IntegrityError: (sqlite3.IntegrityError) NOT NULL constraint failed: reddit_mentions.post_type\nE   [SQL: INSERT INTO reddit_mentions (session_id, reddit_id, post_type, title, content, author, subreddit, url, score, num_comments, upvote_ratio, created_utc, scraped_at, sentiment_score, relevance_score) VALUES (?, ?, ?, ?, ?, ?, ?, ?, ?, ?, ?, ?, ?, ?, ?)]\nE   [parameters: (1, 'test0', None, 'Test post 0 about OpenAI', 'This is a test post discussing OpenAI technology and its impact.', 'test_user', 'technology', 'https://reddit.com/r/technology/comments/test123', 10, 15, None, '2025-05-29 01:32:53.747468', '2025-05-29 01:32:53.747468', -0.5, 0.8)]\nE   (Background on this error at: https://sqlalche.me/e/20/gkpj)\n________________ TestSystemIntegration.test_concurrent_access _________________\n..\\..\\AppData\\Roaming\\Python\\Python312\\site-packages\\sqlalchemy\\engine\\base.py:1964: in _exec_single_context\n    self.dialect.do_execute(\n..\\..\\AppData\\Roaming\\Python\\Python312\\site-packages\\sqlalchemy\\engine\\default.py:942: in do_execute\n    cursor.execute(statement, parameters)\nE   sqlite3.IntegrityError: NOT NULL constraint failed: reddit_mentions.post_type\n\nThe above exception was the direct cause of the following exception:\ntests\\test_integration.py:183: in test_concurrent_access\n    system['db_manager'].add_mention(session_id, mention_copy)\ndatabase\\models.py:133: in add_mention\n    db.commit()\n..\\..\\AppData\\Roaming\\Python\\Python312\\site-packages\\sqlalchemy\\orm\\session.py:2032: in commit\n    trans.commit(_to_root=True)\n<string>:2: in commit\n    ???\n..\\..\\AppData\\Roaming\\Python\\Python312\\site-packages\\sqlalchemy\\orm\\state_changes.py:139: in _go\n    ret_value = fn(self, *arg, **kw)\n..\\..\\AppData\\Roaming\\Python\\Python312\\site-packages\\sqlalchemy\\orm\\session.py:1313: in commit\n    self._prepare_impl()\n<string>:2: in _prepare_impl\n    ???\n..\\..\\AppData\\Roaming\\Python\\Python312\\site-packages\\sqlalchemy\\orm\\state_changes.py:139: in _go\n    ret_value = fn(self, *arg, **kw)\n..\\..\\AppData\\Roaming\\Python\\Python312\\site-packages\\sqlalchemy\\orm\\session.py:1288: in _prepare_impl\n    self.session.flush()\n..\\..\\AppData\\Roaming\\Python\\Python312\\site-packages\\sqlalchemy\\orm\\session.py:4353: in flush\n    self._flush(objects)\n..\\..\\AppData\\Roaming\\Python\\Python312\\site-packages\\sqlalchemy\\orm\\session.py:4488: in _flush\n    with util.safe_reraise():\n..\\..\\AppData\\Roaming\\Python\\Python312\\site-packages\\sqlalchemy\\util\\langhelpers.py:146: in __exit__\n    raise exc_value.with_traceback(exc_tb)\n..\\..\\AppData\\Roaming\\Python\\Python312\\site-packages\\sqlalchemy\\orm\\session.py:4449: in _flush\n    flush_context.execute()\n..\\..\\AppData\\Roaming\\Python\\Python312\\site-packages\\sqlalchemy\\orm\\unitofwork.py:466: in execute\n    rec.execute(self)\n..\\..\\AppData\\Roaming\\Python\\Python312\\site-packages\\sqlalchemy\\orm\\unitofwork.py:642: in execute\n    util.preloaded.orm_persistence.save_obj(\n..\\..\\AppData\\Roaming\\Python\\Python312\\site-packages\\sqlalchemy\\orm\\persistence.py:93: in save_obj\n    _emit_insert_statements(\n..\\..\\AppData\\Roaming\\Python\\Python312\\site-packages\\sqlalchemy\\orm\\persistence.py:1233: in _emit_insert_statements\n    result = connection.execute(\n..\\..\\AppData\\Roaming\\Python\\Python312\\site-packages\\sqlalchemy\\engine\\base.py:1416: in execute\n    return meth(\n..\\..\\AppData\\Roaming\\Python\\Python312\\site-packages\\sqlalchemy\\sql\\elements.py:523: in _execute_on_connection\n    return connection._execute_clauseelement(\n..\\..\\AppData\\Roaming\\Python\\Python312\\site-packages\\sqlalchemy\\engine\\base.py:1638: in _execute_clauseelement\n    ret = self._execute_context(\n..\\..\\AppData\\Roaming\\Python\\Python312\\site-packages\\sqlalchemy\\engine\\base.py:1843: in _execute_context\n    return self._exec_single_context(\n..\\..\\AppData\\Roaming\\Python\\Python312\\site-packages\\sqlalchemy\\engine\\base.py:1983: in _exec_single_context\n    self._handle_dbapi_exception(\n..\\..\\AppData\\Roaming\\Python\\Python312\\site-packages\\sqlalchemy\\engine\\base.py:2352: in _handle_dbapi_exception\n    raise sqlalchemy_exception.with_traceback(exc_info[2]) from e\n..\\..\\AppData\\Roaming\\Python\\Python312\\site-packages\\sqlalchemy\\engine\\base.py:1964: in _exec_single_context\n    self.dialect.do_execute(\n..\\..\\AppData\\Roaming\\Python\\Python312\\site-packages\\sqlalchemy\\engine\\default.py:942: in do_execute\n    cursor.execute(statement, parameters)\nE   sqlalchemy.exc.IntegrityError: (sqlite3.IntegrityError) NOT NULL constraint failed: reddit_mentions.post_type\nE   [SQL: INSERT INTO reddit_mentions (session_id, reddit_id, post_type, title, content, author, subreddit, url, score, num_comments, upvote_ratio, created_utc, scraped_at, sentiment_score, relevance_score) VALUES (?, ?, ?, ?, ?, ?, ?, ?, ?, ?, ?, ?, ?, ?, ?)]\nE   [parameters: (1, 'test0_0', None, 'Test post 0 about OpenAI', 'This is a test post discussing OpenAI technology and its impact.', 'test_user', 'technology', 'https://reddit.com/r/technology/comments/test123', 10, 15, None, '2025-05-29 01:32:53.970468', '2025-05-29 01:32:53.970468', -0.5, 0.8)]\nE   (Background on this error at: https://sqlalche.me/e/20/gkpj)\n_____________ TestSystemIntegration.test_performance_integration ______________\n..\\..\\AppData\\Roaming\\Python\\Python312\\site-packages\\sqlalchemy\\engine\\base.py:1964: in _exec_single_context\n    self.dialect.do_execute(\n..\\..\\AppData\\Roaming\\Python\\Python312\\site-packages\\sqlalchemy\\engine\\default.py:942: in do_execute\n    cursor.execute(statement, parameters)\nE   sqlite3.IntegrityError: NOT NULL constraint failed: reddit_mentions.post_type\n\nThe above exception was the direct cause of the following exception:\ntests\\test_integration.py:230: in test_performance_integration\n    system['db_manager'].add_mention(session_id, mention)\ndatabase\\models.py:133: in add_mention\n    db.commit()\n..\\..\\AppData\\Roaming\\Python\\Python312\\site-packages\\sqlalchemy\\orm\\session.py:2032: in commit\n    trans.commit(_to_root=True)\n<string>:2: in commit\n    ???\n..\\..\\AppData\\Roaming\\Python\\Python312\\site-packages\\sqlalchemy\\orm\\state_changes.py:139: in _go\n    ret_value = fn(self, *arg, **kw)\n..\\..\\AppData\\Roaming\\Python\\Python312\\site-packages\\sqlalchemy\\orm\\session.py:1313: in commit\n    self._prepare_impl()\n<string>:2: in _prepare_impl\n    ???\n..\\..\\AppData\\Roaming\\Python\\Python312\\site-packages\\sqlalchemy\\orm\\state_changes.py:139: in _go\n    ret_value = fn(self, *arg, **kw)\n..\\..\\AppData\\Roaming\\Python\\Python312\\site-packages\\sqlalchemy\\orm\\session.py:1288: in _prepare_impl\n    self.session.flush()\n..\\..\\AppData\\Roaming\\Python\\Python312\\site-packages\\sqlalchemy\\orm\\session.py:4353: in flush\n    self._flush(objects)\n..\\..\\AppData\\Roaming\\Python\\Python312\\site-packages\\sqlalchemy\\orm\\session.py:4488: in _flush\n    with util.safe_reraise():\n..\\..\\AppData\\Roaming\\Python\\Python312\\site-packages\\sqlalchemy\\util\\langhelpers.py:146: in __exit__\n    raise exc_value.with_traceback(exc_tb)\n..\\..\\AppData\\Roaming\\Python\\Python312\\site-packages\\sqlalchemy\\orm\\session.py:4449: in _flush\n    flush_context.execute()\n..\\..\\AppData\\Roaming\\Python\\Python312\\site-packages\\sqlalchemy\\orm\\unitofwork.py:466: in execute\n    rec.execute(self)\n..\\..\\AppData\\Roaming\\Python\\Python312\\site-packages\\sqlalchemy\\orm\\unitofwork.py:642: in execute\n    util.preloaded.orm_persistence.save_obj(\n..\\..\\AppData\\Roaming\\Python\\Python312\\site-packages\\sqlalchemy\\orm\\persistence.py:93: in save_obj\n    _emit_insert_statements(\n..\\..\\AppData\\Roaming\\Python\\Python312\\site-packages\\sqlalchemy\\orm\\persistence.py:1233: in _emit_insert_statements\n    result = connection.execute(\n..\\..\\AppData\\Roaming\\Python\\Python312\\site-packages\\sqlalchemy\\engine\\base.py:1416: in execute\n    return meth(\n..\\..\\AppData\\Roaming\\Python\\Python312\\site-packages\\sqlalchemy\\sql\\elements.py:523: in _execute_on_connection\n    return connection._execute_clauseelement(\n..\\..\\AppData\\Roaming\\Python\\Python312\\site-packages\\sqlalchemy\\engine\\base.py:1638: in _execute_clauseelement\n    ret = self._execute_context(\n..\\..\\AppData\\Roaming\\Python\\Python312\\site-packages\\sqlalchemy\\engine\\base.py:1843: in _execute_context\n    return self._exec_single_context(\n..\\..\\AppData\\Roaming\\Python\\Python312\\site-packages\\sqlalchemy\\engine\\base.py:1983: in _exec_single_context\n    self._handle_dbapi_exception(\n..\\..\\AppData\\Roaming\\Python\\Python312\\site-packages\\sqlalchemy\\engine\\base.py:2352: in _handle_dbapi_exception\n    raise sqlalchemy_exception.with_traceback(exc_info[2]) from e\n..\\..\\AppData\\Roaming\\Python\\Python312\\site-packages\\sqlalchemy\\engine\\base.py:1964: in _exec_single_context\n    self.dialect.do_execute(\n..\\..\\AppData\\Roaming\\Python\\Python312\\site-packages\\sqlalchemy\\engine\\default.py:942: in do_execute\n    cursor.execute(statement, parameters)\nE   sqlalchemy.exc.IntegrityError: (sqlite3.IntegrityError) NOT NULL constraint failed: reddit_mentions.post_type\nE   [SQL: INSERT INTO reddit_mentions (session_id, reddit_id, post_type, title, content, author, subreddit, url, score, num_comments, upvote_ratio, created_utc, scraped_at, sentiment_score, relevance_score) VALUES (?, ?, ?, ?, ?, ?, ?, ?, ?, ?, ?, ?, ?, ?, ?)]\nE   [parameters: (1, 'perf_test_0', None, 'Performance test 0', 'Content 0', 'user_0', 'test', None, 0, 0, None, '2025-05-29 01:32:54.200469', '2025-05-29 01:32:54.200469', 0.5, 0.7)]\nE   (Background on this error at: https://sqlalche.me/e/20/gkpj)\n_________________ TestAPIIntegration.test_api_search_endpoint _________________\ntests\\test_integration.py:277: in test_api_search_endpoint\n    assert response.status_code == 200\nE   assert 500 == 200\nE    +  where 500 = <Response [500 Internal Server Error]>.status_code\n------------------------------ Captured log call ------------------------------\nERROR    api.endpoints:endpoints.py:187 Error starting search: 'int' object has no attribute 'id'\n______________ TestCacheIntegration.test_cache_integration_basic ______________\ntests\\test_integration.py:323: in test_cache_integration_basic\n    assert retrieved == test_value\nE   AssertionError: assert None == {'data': 'test_integration_value'}\n_____________ TestCacheIntegration.test_cache_performance_impact ______________\ntests\\test_integration.py:337: in test_cache_performance_impact\n    assert retrieved == value\nE   AssertionError: assert None == {'data': 'value_0'}\n============================== warnings summary ===============================\ndatabase\\models.py:10\n  C:\\Users\\Devansh\\Downloads\\intern_application_round1\\database\\models.py:10: MovedIn20Warning: The ``declarative_base()`` function is now available as sqlalchemy.orm.declarative_base(). (deprecated since: 2.0) (Background on SQLAlchemy 2.0 at: https://sqlalche.me/e/b8d9)\n    Base = declarative_base()\n\ntests\\test_analytics.py:35\n  C:\\Users\\Devansh\\Downloads\\intern_application_round1\\tests\\test_analytics.py:35: PytestUnknownMarkWarning: Unknown pytest.mark.smoke - is this a typo?  You can register custom marks to avoid this warning - for details, see https://docs.pytest.org/en/stable/how-to/mark.html\n    @pytest.mark.smoke\n\ntests\\test_analytics.py:36\n  C:\\Users\\Devansh\\Downloads\\intern_application_round1\\tests\\test_analytics.py:36: PytestUnknownMarkWarning: Unknown pytest.mark.unit - is this a typo?  You can register custom marks to avoid this warning - for details, see https://docs.pytest.org/en/stable/how-to/mark.html\n    @pytest.mark.unit\n\ntests\\test_analytics.py:43\n  C:\\Users\\Devansh\\Downloads\\intern_application_round1\\tests\\test_analytics.py:43: PytestUnknownMarkWarning: Unknown pytest.mark.smoke - is this a typo?  You can register custom marks to avoid this warning - for details, see https://docs.pytest.org/en/stable/how-to/mark.html\n    @pytest.mark.smoke\n\ntests\\test_analytics.py:44\n  C:\\Users\\Devansh\\Downloads\\intern_application_round1\\tests\\test_analytics.py:44: PytestUnknownMarkWarning: Unknown pytest.mark.unit - is this a typo?  You can register custom marks to avoid this warning - for details, see https://docs.pytest.org/en/stable/how-to/mark.html\n    @pytest.mark.unit\n\ntests\\test_analytics.py:76\n  C:\\Users\\Devansh\\Downloads\\intern_application_round1\\tests\\test_analytics.py:76: PytestUnknownMarkWarning: Unknown pytest.mark.smoke - is this a typo?  You can register custom marks to avoid this warning - for details, see https://docs.pytest.org/en/stable/how-to/mark.html\n    @pytest.mark.smoke\n\ntests\\test_analytics.py:77\n  C:\\Users\\Devansh\\Downloads\\intern_application_round1\\tests\\test_analytics.py:77: PytestUnknownMarkWarning: Unknown pytest.mark.unit - is this a typo?  You can register custom marks to avoid this warning - for details, see https://docs.pytest.org/en/stable/how-to/mark.html\n    @pytest.mark.unit\n\ntests\\test_analytics.py:109\n  C:\\Users\\Devansh\\Downloads\\intern_application_round1\\tests\\test_analytics.py:109: PytestUnknownMarkWarning: Unknown pytest.mark.unit - is this a typo?  You can register custom marks to avoid this warning - for details, see https://docs.pytest.org/en/stable/how-to/mark.html\n    @pytest.mark.unit\n\ntests\\test_analytics.py:138\n  C:\\Users\\Devansh\\Downloads\\intern_application_round1\\tests\\test_analytics.py:138: PytestUnknownMarkWarning: Unknown pytest.mark.unit - is this a typo?  You can register custom marks to avoid this warning - for details, see https://docs.pytest.org/en/stable/how-to/mark.html\n    @pytest.mark.unit\n\ntests\\test_analytics.py:169\n  C:\\Users\\Devansh\\Downloads\\intern_application_round1\\tests\\test_analytics.py:169: PytestUnknownMarkWarning: Unknown pytest.mark.unit - is this a typo?  You can register custom marks to avoid this warning - for details, see https://docs.pytest.org/en/stable/how-to/mark.html\n    @pytest.mark.unit\n\ntests\\test_analytics.py:196\n  C:\\Users\\Devansh\\Downloads\\intern_application_round1\\tests\\test_analytics.py:196: PytestUnknownMarkWarning: Unknown pytest.mark.unit - is this a typo?  You can register custom marks to avoid this warning - for details, see https://docs.pytest.org/en/stable/how-to/mark.html\n    @pytest.mark.unit\n\ntests\\test_analytics.py:223\n  C:\\Users\\Devansh\\Downloads\\intern_application_round1\\tests\\test_analytics.py:223: PytestUnknownMarkWarning: Unknown pytest.mark.unit - is this a typo?  You can register custom marks to avoid this warning - for details, see https://docs.pytest.org/en/stable/how-to/mark.html\n    @pytest.mark.unit\n\ntests\\test_analytics.py:258\n  C:\\Users\\Devansh\\Downloads\\intern_application_round1\\tests\\test_analytics.py:258: PytestUnknownMarkWarning: Unknown pytest.mark.unit - is this a typo?  You can register custom marks to avoid this warning - for details, see https://docs.pytest.org/en/stable/how-to/mark.html\n    @pytest.mark.unit\n\ntests\\test_analytics.py:291\n  C:\\Users\\Devansh\\Downloads\\intern_application_round1\\tests\\test_analytics.py:291: PytestUnknownMarkWarning: Unknown pytest.mark.unit - is this a typo?  You can register custom marks to avoid this warning - for details, see https://docs.pytest.org/en/stable/how-to/mark.html\n    @pytest.mark.unit\n\ntests\\test_analytics.py:308\n  C:\\Users\\Devansh\\Downloads\\intern_application_round1\\tests\\test_analytics.py:308: PytestUnknownMarkWarning: Unknown pytest.mark.unit - is this a typo?  You can register custom marks to avoid this warning - for details, see https://docs.pytest.org/en/stable/how-to/mark.html\n    @pytest.mark.unit\n\ntests\\test_analytics.py:351\n  C:\\Users\\Devansh\\Downloads\\intern_application_round1\\tests\\test_analytics.py:351: PytestUnknownMarkWarning: Unknown pytest.mark.unit - is this a typo?  You can register custom marks to avoid this warning - for details, see https://docs.pytest.org/en/stable/how-to/mark.html\n    @pytest.mark.unit\n\ntests\\test_analytics.py:359\n  C:\\Users\\Devansh\\Downloads\\intern_application_round1\\tests\\test_analytics.py:359: PytestUnknownMarkWarning: Unknown pytest.mark.unit - is this a typo?  You can register custom marks to avoid this warning - for details, see https://docs.pytest.org/en/stable/how-to/mark.html\n    @pytest.mark.unit\n\ntests\\test_analytics.py:371\n  C:\\Users\\Devansh\\Downloads\\intern_application_round1\\tests\\test_analytics.py:371: PytestUnknownMarkWarning: Unknown pytest.mark.unit - is this a typo?  You can register custom marks to avoid this warning - for details, see https://docs.pytest.org/en/stable/how-to/mark.html\n    @pytest.mark.unit\n\ntests\\test_analytics.py:616\n  C:\\Users\\Devansh\\Downloads\\intern_application_round1\\tests\\test_analytics.py:616: PytestUnknownMarkWarning: Unknown pytest.mark.integration - is this a typo?  You can register custom marks to avoid this warning - for details, see https://docs.pytest.org/en/stable/how-to/mark.html\n    @pytest.mark.integration\n\ntests\\test_analytics.py:642\n  C:\\Users\\Devansh\\Downloads\\intern_application_round1\\tests\\test_analytics.py:642: PytestUnknownMarkWarning: Unknown pytest.mark.integration - is this a typo?  You can register custom marks to avoid this warning - for details, see https://docs.pytest.org/en/stable/how-to/mark.html\n    @pytest.mark.integration\n\ntests\\test_analytics.py:659\n  C:\\Users\\Devansh\\Downloads\\intern_application_round1\\tests\\test_analytics.py:659: PytestUnknownMarkWarning: Unknown pytest.mark.integration - is this a typo?  You can register custom marks to avoid this warning - for details, see https://docs.pytest.org/en/stable/how-to/mark.html\n    @pytest.mark.integration\n\ntests\\test_database.py:16\n  C:\\Users\\Devansh\\Downloads\\intern_application_round1\\tests\\test_database.py:16: PytestUnknownMarkWarning: Unknown pytest.mark.smoke - is this a typo?  You can register custom marks to avoid this warning - for details, see https://docs.pytest.org/en/stable/how-to/mark.html\n    @pytest.mark.smoke\n\ntests\\test_database.py:17\n  C:\\Users\\Devansh\\Downloads\\intern_application_round1\\tests\\test_database.py:17: PytestUnknownMarkWarning: Unknown pytest.mark.unit - is this a typo?  You can register custom marks to avoid this warning - for details, see https://docs.pytest.org/en/stable/how-to/mark.html\n    @pytest.mark.unit\n\ntests\\test_database.py:24\n  C:\\Users\\Devansh\\Downloads\\intern_application_round1\\tests\\test_database.py:24: PytestUnknownMarkWarning: Unknown pytest.mark.smoke - is this a typo?  You can register custom marks to avoid this warning - for details, see https://docs.pytest.org/en/stable/how-to/mark.html\n    @pytest.mark.smoke\n\ntests\\test_database.py:25\n  C:\\Users\\Devansh\\Downloads\\intern_application_round1\\tests\\test_database.py:25: PytestUnknownMarkWarning: Unknown pytest.mark.unit - is this a typo?  You can register custom marks to avoid this warning - for details, see https://docs.pytest.org/en/stable/how-to/mark.html\n    @pytest.mark.unit\n\ntests\\test_database.py:41\n  C:\\Users\\Devansh\\Downloads\\intern_application_round1\\tests\\test_database.py:41: PytestUnknownMarkWarning: Unknown pytest.mark.unit - is this a typo?  You can register custom marks to avoid this warning - for details, see https://docs.pytest.org/en/stable/how-to/mark.html\n    @pytest.mark.unit\n\ntests\\test_database.py:70\n  C:\\Users\\Devansh\\Downloads\\intern_application_round1\\tests\\test_database.py:70: PytestUnknownMarkWarning: Unknown pytest.mark.unit - is this a typo?  You can register custom marks to avoid this warning - for details, see https://docs.pytest.org/en/stable/how-to/mark.html\n    @pytest.mark.unit\n\ntests\\test_database.py:98\n  C:\\Users\\Devansh\\Downloads\\intern_application_round1\\tests\\test_database.py:98: PytestUnknownMarkWarning: Unknown pytest.mark.unit - is this a typo?  You can register custom marks to avoid this warning - for details, see https://docs.pytest.org/en/stable/how-to/mark.html\n    @pytest.mark.unit\n\ntests\\test_database.py:112\n  C:\\Users\\Devansh\\Downloads\\intern_application_round1\\tests\\test_database.py:112: PytestUnknownMarkWarning: Unknown pytest.mark.unit - is this a typo?  You can register custom marks to avoid this warning - for details, see https://docs.pytest.org/en/stable/how-to/mark.html\n    @pytest.mark.unit\n\ntests\\test_database.py:137\n  C:\\Users\\Devansh\\Downloads\\intern_application_round1\\tests\\test_database.py:137: PytestUnknownMarkWarning: Unknown pytest.mark.unit - is this a typo?  You can register custom marks to avoid this warning - for details, see https://docs.pytest.org/en/stable/how-to/mark.html\n    @pytest.mark.unit\n\ntests\\test_database.py:181\n  C:\\Users\\Devansh\\Downloads\\intern_application_round1\\tests\\test_database.py:181: PytestUnknownMarkWarning: Unknown pytest.mark.unit - is this a typo?  You can register custom marks to avoid this warning - for details, see https://docs.pytest.org/en/stable/how-to/mark.html\n    @pytest.mark.unit\n\ntests\\test_database.py:214\n  C:\\Users\\Devansh\\Downloads\\intern_application_round1\\tests\\test_database.py:214: PytestUnknownMarkWarning: Unknown pytest.mark.unit - is this a typo?  You can register custom marks to avoid this warning - for details, see https://docs.pytest.org/en/stable/how-to/mark.html\n    @pytest.mark.unit\n\ntests\\test_database.py:246\n  C:\\Users\\Devansh\\Downloads\\intern_application_round1\\tests\\test_database.py:246: PytestUnknownMarkWarning: Unknown pytest.mark.unit - is this a typo?  You can register custom marks to avoid this warning - for details, see https://docs.pytest.org/en/stable/how-to/mark.html\n    @pytest.mark.unit\n\ntests\\test_database.py:277\n  C:\\Users\\Devansh\\Downloads\\intern_application_round1\\tests\\test_database.py:277: PytestUnknownMarkWarning: Unknown pytest.mark.unit - is this a typo?  You can register custom marks to avoid this warning - for details, see https://docs.pytest.org/en/stable/how-to/mark.html\n    @pytest.mark.unit\n\ntests\\test_database.py:299\n  C:\\Users\\Devansh\\Downloads\\intern_application_round1\\tests\\test_database.py:299: PytestUnknownMarkWarning: Unknown pytest.mark.unit - is this a typo?  You can register custom marks to avoid this warning - for details, see https://docs.pytest.org/en/stable/how-to/mark.html\n    @pytest.mark.unit\n\ntests\\test_database.py:314\n  C:\\Users\\Devansh\\Downloads\\intern_application_round1\\tests\\test_database.py:314: PytestUnknownMarkWarning: Unknown pytest.mark.unit - is this a typo?  You can register custom marks to avoid this warning - for details, see https://docs.pytest.org/en/stable/how-to/mark.html\n    @pytest.mark.unit\n\ntests\\test_database.py:334\n  C:\\Users\\Devansh\\Downloads\\intern_application_round1\\tests\\test_database.py:334: PytestUnknownMarkWarning: Unknown pytest.mark.unit - is this a typo?  You can register custom marks to avoid this warning - for details, see https://docs.pytest.org/en/stable/how-to/mark.html\n    @pytest.mark.unit\n\ntests\\test_database.py:360\n  C:\\Users\\Devansh\\Downloads\\intern_application_round1\\tests\\test_database.py:360: PytestUnknownMarkWarning: Unknown pytest.mark.unit - is this a typo?  You can register custom marks to avoid this warning - for details, see https://docs.pytest.org/en/stable/how-to/mark.html\n    @pytest.mark.unit\n\ntests\\test_database.py:397\n  C:\\Users\\Devansh\\Downloads\\intern_application_round1\\tests\\test_database.py:397: PytestUnknownMarkWarning: Unknown pytest.mark.unit - is this a typo?  You can register custom marks to avoid this warning - for details, see https://docs.pytest.org/en/stable/how-to/mark.html\n    @pytest.mark.unit\n\ntests\\test_database.py:412\n  C:\\Users\\Devansh\\Downloads\\intern_application_round1\\tests\\test_database.py:412: PytestUnknownMarkWarning: Unknown pytest.mark.unit - is this a typo?  You can register custom marks to avoid this warning - for details, see https://docs.pytest.org/en/stable/how-to/mark.html\n    @pytest.mark.unit\n\ntests\\test_database.py:441\n  C:\\Users\\Devansh\\Downloads\\intern_application_round1\\tests\\test_database.py:441: PytestUnknownMarkWarning: Unknown pytest.mark.unit - is this a typo?  You can register custom marks to avoid this warning - for details, see https://docs.pytest.org/en/stable/how-to/mark.html\n    @pytest.mark.unit\n\ntests\\test_database.py:472\n  C:\\Users\\Devansh\\Downloads\\intern_application_round1\\tests\\test_database.py:472: PytestUnknownMarkWarning: Unknown pytest.mark.unit - is this a typo?  You can register custom marks to avoid this warning - for details, see https://docs.pytest.org/en/stable/how-to/mark.html\n    @pytest.mark.unit\n\ntests\\test_integration.py:42\n  C:\\Users\\Devansh\\Downloads\\intern_application_round1\\tests\\test_integration.py:42: PytestUnknownMarkWarning: Unknown pytest.mark.integration - is this a typo?  You can register custom marks to avoid this warning - for details, see https://docs.pytest.org/en/stable/how-to/mark.html\n    @pytest.mark.integration\n\ntests\\test_integration.py:89\n  C:\\Users\\Devansh\\Downloads\\intern_application_round1\\tests\\test_integration.py:89: PytestUnknownMarkWarning: Unknown pytest.mark.integration - is this a typo?  You can register custom marks to avoid this warning - for details, see https://docs.pytest.org/en/stable/how-to/mark.html\n    @pytest.mark.integration\n\ntests\\test_integration.py:112\n  C:\\Users\\Devansh\\Downloads\\intern_application_round1\\tests\\test_integration.py:112: PytestUnknownMarkWarning: Unknown pytest.mark.integration - is this a typo?  You can register custom marks to avoid this warning - for details, see https://docs.pytest.org/en/stable/how-to/mark.html\n    @pytest.mark.integration\n\ntests\\test_integration.py:144\n  C:\\Users\\Devansh\\Downloads\\intern_application_round1\\tests\\test_integration.py:144: PytestUnknownMarkWarning: Unknown pytest.mark.integration - is this a typo?  You can register custom marks to avoid this warning - for details, see https://docs.pytest.org/en/stable/how-to/mark.html\n    @pytest.mark.integration\n\ntests\\test_integration.py:167\n  C:\\Users\\Devansh\\Downloads\\intern_application_round1\\tests\\test_integration.py:167: PytestUnknownMarkWarning: Unknown pytest.mark.integration - is this a typo?  You can register custom marks to avoid this warning - for details, see https://docs.pytest.org/en/stable/how-to/mark.html\n    @pytest.mark.integration\n\ntests\\test_integration.py:204\n  C:\\Users\\Devansh\\Downloads\\intern_application_round1\\tests\\test_integration.py:204: PytestUnknownMarkWarning: Unknown pytest.mark.integration - is this a typo?  You can register custom marks to avoid this warning - for details, see https://docs.pytest.org/en/stable/how-to/mark.html\n    @pytest.mark.integration\n\ntests\\test_integration.py:255\n  C:\\Users\\Devansh\\Downloads\\intern_application_round1\\tests\\test_integration.py:255: PytestUnknownMarkWarning: Unknown pytest.mark.integration - is this a typo?  You can register custom marks to avoid this warning - for details, see https://docs.pytest.org/en/stable/how-to/mark.html\n    @pytest.mark.integration\n\ntests\\test_integration.py:265\n  C:\\Users\\Devansh\\Downloads\\intern_application_round1\\tests\\test_integration.py:265: PytestUnknownMarkWarning: Unknown pytest.mark.integration - is this a typo?  You can register custom marks to avoid this warning - for details, see https://docs.pytest.org/en/stable/how-to/mark.html\n    @pytest.mark.integration\n\ntests\\test_integration.py:284\n  C:\\Users\\Devansh\\Downloads\\intern_application_round1\\tests\\test_integration.py:284: PytestUnknownMarkWarning: Unknown pytest.mark.integration - is this a typo?  You can register custom marks to avoid this warning - for details, see https://docs.pytest.org/en/stable/how-to/mark.html\n    @pytest.mark.integration\n\ntests\\test_integration.py:308\n  C:\\Users\\Devansh\\Downloads\\intern_application_round1\\tests\\test_integration.py:308: PytestUnknownMarkWarning: Unknown pytest.mark.integration - is this a typo?  You can register custom marks to avoid this warning - for details, see https://docs.pytest.org/en/stable/how-to/mark.html\n    @pytest.mark.integration\n\ntests\\test_integration.py:325\n  C:\\Users\\Devansh\\Downloads\\intern_application_round1\\tests\\test_integration.py:325: PytestUnknownMarkWarning: Unknown pytest.mark.integration - is this a typo?  You can register custom marks to avoid this warning - for details, see https://docs.pytest.org/en/stable/how-to/mark.html\n    @pytest.mark.integration\n\ntests\\test_integration.py:348\n  C:\\Users\\Devansh\\Downloads\\intern_application_round1\\tests\\test_integration.py:348: PytestUnknownMarkWarning: Unknown pytest.mark.integration - is this a typo?  You can register custom marks to avoid this warning - for details, see https://docs.pytest.org/en/stable/how-to/mark.html\n    @pytest.mark.integration\n\ntests\\test_integration.py:368\n  C:\\Users\\Devansh\\Downloads\\intern_application_round1\\tests\\test_integration.py:368: PytestUnknownMarkWarning: Unknown pytest.mark.integration - is this a typo?  You can register custom marks to avoid this warning - for details, see https://docs.pytest.org/en/stable/how-to/mark.html\n    @pytest.mark.integration\n\ntests\\test_integration.py:392\n  C:\\Users\\Devansh\\Downloads\\intern_application_round1\\tests\\test_integration.py:392: PytestUnknownMarkWarning: Unknown pytest.mark.integration - is this a typo?  You can register custom marks to avoid this warning - for details, see https://docs.pytest.org/en/stable/how-to/mark.html\n    @pytest.mark.integration\n\ntests\\test_integration.py:424\n  C:\\Users\\Devansh\\Downloads\\intern_application_round1\\tests\\test_integration.py:424: PytestUnknownMarkWarning: Unknown pytest.mark.integration - is this a typo?  You can register custom marks to avoid this warning - for details, see https://docs.pytest.org/en/stable/how-to/mark.html\n    @pytest.mark.integration\n\ntests\\test_integration.py:449\n  C:\\Users\\Devansh\\Downloads\\intern_application_round1\\tests\\test_integration.py:449: PytestUnknownMarkWarning: Unknown pytest.mark.integration - is this a typo?  You can register custom marks to avoid this warning - for details, see https://docs.pytest.org/en/stable/how-to/mark.html\n    @pytest.mark.integration\n\ntests\\test_performance.py:24\n  C:\\Users\\Devansh\\Downloads\\intern_application_round1\\tests\\test_performance.py:24: PytestUnknownMarkWarning: Unknown pytest.mark.performance - is this a typo?  You can register custom marks to avoid this warning - for details, see https://docs.pytest.org/en/stable/how-to/mark.html\n    @pytest.mark.performance\n\ntests\\test_performance.py:61\n  C:\\Users\\Devansh\\Downloads\\intern_application_round1\\tests\\test_performance.py:61: PytestUnknownMarkWarning: Unknown pytest.mark.performance - is this a typo?  You can register custom marks to avoid this warning - for details, see https://docs.pytest.org/en/stable/how-to/mark.html\n    @pytest.mark.performance\n\ntests\\test_performance.py:89\n  C:\\Users\\Devansh\\Downloads\\intern_application_round1\\tests\\test_performance.py:89: PytestUnknownMarkWarning: Unknown pytest.mark.performance - is this a typo?  You can register custom marks to avoid this warning - for details, see https://docs.pytest.org/en/stable/how-to/mark.html\n    @pytest.mark.performance\n\ntests\\test_performance.py:137\n  C:\\Users\\Devansh\\Downloads\\intern_application_round1\\tests\\test_performance.py:137: PytestUnknownMarkWarning: Unknown pytest.mark.performance - is this a typo?  You can register custom marks to avoid this warning - for details, see https://docs.pytest.org/en/stable/how-to/mark.html\n    @pytest.mark.performance\n\ntests\\test_performance.py:165\n  C:\\Users\\Devansh\\Downloads\\intern_application_round1\\tests\\test_performance.py:165: PytestUnknownMarkWarning: Unknown pytest.mark.performance - is this a typo?  You can register custom marks to avoid this warning - for details, see https://docs.pytest.org/en/stable/how-to/mark.html\n    @pytest.mark.performance\n\ntests\\test_performance.py:198\n  C:\\Users\\Devansh\\Downloads\\intern_application_round1\\tests\\test_performance.py:198: PytestUnknownMarkWarning: Unknown pytest.mark.performance - is this a typo?  You can register custom marks to avoid this warning - for details, see https://docs.pytest.org/en/stable/how-to/mark.html\n    @pytest.mark.performance\n\ntests\\test_performance.py:232\n  C:\\Users\\Devansh\\Downloads\\intern_application_round1\\tests\\test_performance.py:232: PytestUnknownMarkWarning: Unknown pytest.mark.performance - is this a typo?  You can register custom marks to avoid this warning - for details, see https://docs.pytest.org/en/stable/how-to/mark.html\n    @pytest.mark.performance\n\ntests\\test_performance.py:278\n  C:\\Users\\Devansh\\Downloads\\intern_application_round1\\tests\\test_performance.py:278: PytestUnknownMarkWarning: Unknown pytest.mark.performance - is this a typo?  You can register custom marks to avoid this warning - for details, see https://docs.pytest.org/en/stable/how-to/mark.html\n    @pytest.mark.performance\n\ntests\\test_performance.py:328\n  C:\\Users\\Devansh\\Downloads\\intern_application_round1\\tests\\test_performance.py:328: PytestUnknownMarkWarning: Unknown pytest.mark.performance - is this a typo?  You can register custom marks to avoid this warning - for details, see https://docs.pytest.org/en/stable/how-to/mark.html\n    @pytest.mark.performance\n\ntests\\test_performance.py:355\n  C:\\Users\\Devansh\\Downloads\\intern_application_round1\\tests\\test_performance.py:355: PytestUnknownMarkWarning: Unknown pytest.mark.performance - is this a typo?  You can register custom marks to avoid this warning - for details, see https://docs.pytest.org/en/stable/how-to/mark.html\n    @pytest.mark.performance\n\ntests\\test_performance.py:386\n  C:\\Users\\Devansh\\Downloads\\intern_application_round1\\tests\\test_performance.py:386: PytestUnknownMarkWarning: Unknown pytest.mark.performance - is this a typo?  You can register custom marks to avoid this warning - for details, see https://docs.pytest.org/en/stable/how-to/mark.html\n    @pytest.mark.performance\n\ntests\\test_performance.py:420\n  C:\\Users\\Devansh\\Downloads\\intern_application_round1\\tests\\test_performance.py:420: PytestUnknownMarkWarning: Unknown pytest.mark.performance - is this a typo?  You can register custom marks to avoid this warning - for details, see https://docs.pytest.org/en/stable/how-to/mark.html\n    @pytest.mark.performance\n\ntests\\test_runner.py:19\n  C:\\Users\\Devansh\\Downloads\\intern_application_round1\\tests\\test_runner.py:19: PytestCollectionWarning: cannot collect test class 'TestRunner' because it has a __init__ constructor (from: tests/test_runner.py)\n    class TestRunner:\n\ntests\\test_scraper.py:20\n  C:\\Users\\Devansh\\Downloads\\intern_application_round1\\tests\\test_scraper.py:20: PytestUnknownMarkWarning: Unknown pytest.mark.smoke - is this a typo?  You can register custom marks to avoid this warning - for details, see https://docs.pytest.org/en/stable/how-to/mark.html\n    @pytest.mark.smoke\n\ntests\\test_scraper.py:21\n  C:\\Users\\Devansh\\Downloads\\intern_application_round1\\tests\\test_scraper.py:21: PytestUnknownMarkWarning: Unknown pytest.mark.unit - is this a typo?  You can register custom marks to avoid this warning - for details, see https://docs.pytest.org/en/stable/how-to/mark.html\n    @pytest.mark.unit\n\ntests\\test_scraper.py:30\n  C:\\Users\\Devansh\\Downloads\\intern_application_round1\\tests\\test_scraper.py:30: PytestUnknownMarkWarning: Unknown pytest.mark.smoke - is this a typo?  You can register custom marks to avoid this warning - for details, see https://docs.pytest.org/en/stable/how-to/mark.html\n    @pytest.mark.smoke\n\ntests\\test_scraper.py:31\n  C:\\Users\\Devansh\\Downloads\\intern_application_round1\\tests\\test_scraper.py:31: PytestUnknownMarkWarning: Unknown pytest.mark.unit - is this a typo?  You can register custom marks to avoid this warning - for details, see https://docs.pytest.org/en/stable/how-to/mark.html\n    @pytest.mark.unit\n\ntests\\test_scraper.py:93\n  C:\\Users\\Devansh\\Downloads\\intern_application_round1\\tests\\test_scraper.py:93: PytestUnknownMarkWarning: Unknown pytest.mark.unit - is this a typo?  You can register custom marks to avoid this warning - for details, see https://docs.pytest.org/en/stable/how-to/mark.html\n    @pytest.mark.unit\n\ntests\\test_scraper.py:489\n  C:\\Users\\Devansh\\Downloads\\intern_application_round1\\tests\\test_scraper.py:489: PytestUnknownMarkWarning: Unknown pytest.mark.unit - is this a typo?  You can register custom marks to avoid this warning - for details, see https://docs.pytest.org/en/stable/how-to/mark.html\n    @pytest.mark.unit\n\ntests\\test_scraper.py:500\n  C:\\Users\\Devansh\\Downloads\\intern_application_round1\\tests\\test_scraper.py:500: PytestUnknownMarkWarning: Unknown pytest.mark.unit - is this a typo?  You can register custom marks to avoid this warning - for details, see https://docs.pytest.org/en/stable/how-to/mark.html\n    @pytest.mark.unit\n\ntests\\test_scraper.py:515\n  C:\\Users\\Devansh\\Downloads\\intern_application_round1\\tests\\test_scraper.py:515: PytestUnknownMarkWarning: Unknown pytest.mark.unit - is this a typo?  You can register custom marks to avoid this warning - for details, see https://docs.pytest.org/en/stable/how-to/mark.html\n    @pytest.mark.unit\n\ntests\\test_scraper.py:531\n  C:\\Users\\Devansh\\Downloads\\intern_application_round1\\tests\\test_scraper.py:531: PytestUnknownMarkWarning: Unknown pytest.mark.unit - is this a typo?  You can register custom marks to avoid this warning - for details, see https://docs.pytest.org/en/stable/how-to/mark.html\n    @pytest.mark.unit\n\ntests\\test_scraper.py:567\n  C:\\Users\\Devansh\\Downloads\\intern_application_round1\\tests\\test_scraper.py:567: PytestUnknownMarkWarning: Unknown pytest.mark.unit - is this a typo?  You can register custom marks to avoid this warning - for details, see https://docs.pytest.org/en/stable/how-to/mark.html\n    @pytest.mark.unit\n\ntests\\test_scraper.py:581\n  C:\\Users\\Devansh\\Downloads\\intern_application_round1\\tests\\test_scraper.py:581: PytestUnknownMarkWarning: Unknown pytest.mark.unit - is this a typo?  You can register custom marks to avoid this warning - for details, see https://docs.pytest.org/en/stable/how-to/mark.html\n    @pytest.mark.unit\n\ntests\\test_security.py:19\n  C:\\Users\\Devansh\\Downloads\\intern_application_round1\\tests\\test_security.py:19: PytestUnknownMarkWarning: Unknown pytest.mark.security - is this a typo?  You can register custom marks to avoid this warning - for details, see https://docs.pytest.org/en/stable/how-to/mark.html\n    @pytest.mark.security\n\ntests\\test_security.py:46\n  C:\\Users\\Devansh\\Downloads\\intern_application_round1\\tests\\test_security.py:46: PytestUnknownMarkWarning: Unknown pytest.mark.security - is this a typo?  You can register custom marks to avoid this warning - for details, see https://docs.pytest.org/en/stable/how-to/mark.html\n    @pytest.mark.security\n\ntests\\test_security.py:81\n  C:\\Users\\Devansh\\Downloads\\intern_application_round1\\tests\\test_security.py:81: PytestUnknownMarkWarning: Unknown pytest.mark.security - is this a typo?  You can register custom marks to avoid this warning - for details, see https://docs.pytest.org/en/stable/how-to/mark.html\n    @pytest.mark.security\n\ntests\\test_security.py:109\n  C:\\Users\\Devansh\\Downloads\\intern_application_round1\\tests\\test_security.py:109: PytestUnknownMarkWarning: Unknown pytest.mark.security - is this a typo?  You can register custom marks to avoid this warning - for details, see https://docs.pytest.org/en/stable/how-to/mark.html\n    @pytest.mark.security\n\ntests\\test_security.py:144\n  C:\\Users\\Devansh\\Downloads\\intern_application_round1\\tests\\test_security.py:144: PytestUnknownMarkWarning: Unknown pytest.mark.security - is this a typo?  You can register custom marks to avoid this warning - for details, see https://docs.pytest.org/en/stable/how-to/mark.html\n    @pytest.mark.security\n\ntests\\test_security.py:170\n  C:\\Users\\Devansh\\Downloads\\intern_application_round1\\tests\\test_security.py:170: PytestUnknownMarkWarning: Unknown pytest.mark.security - is this a typo?  You can register custom marks to avoid this warning - for details, see https://docs.pytest.org/en/stable/how-to/mark.html\n    @pytest.mark.security\n\ntests\\test_security.py:202\n  C:\\Users\\Devansh\\Downloads\\intern_application_round1\\tests\\test_security.py:202: PytestUnknownMarkWarning: Unknown pytest.mark.security - is this a typo?  You can register custom marks to avoid this warning - for details, see https://docs.pytest.org/en/stable/how-to/mark.html\n    @pytest.mark.security\n\ntests\\test_security.py:222\n  C:\\Users\\Devansh\\Downloads\\intern_application_round1\\tests\\test_security.py:222: PytestUnknownMarkWarning: Unknown pytest.mark.security - is this a typo?  You can register custom marks to avoid this warning - for details, see https://docs.pytest.org/en/stable/how-to/mark.html\n    @pytest.mark.security\n\ntests\\test_security.py:249\n  C:\\Users\\Devansh\\Downloads\\intern_application_round1\\tests\\test_security.py:249: PytestUnknownMarkWarning: Unknown pytest.mark.security - is this a typo?  You can register custom marks to avoid this warning - for details, see https://docs.pytest.org/en/stable/how-to/mark.html\n    @pytest.mark.security\n\ntests\\test_security.py:271\n  C:\\Users\\Devansh\\Downloads\\intern_application_round1\\tests\\test_security.py:271: PytestUnknownMarkWarning: Unknown pytest.mark.security - is this a typo?  You can register custom marks to avoid this warning - for details, see https://docs.pytest.org/en/stable/how-to/mark.html\n    @pytest.mark.security\n\ntests\\test_security.py:290\n  C:\\Users\\Devansh\\Downloads\\intern_application_round1\\tests\\test_security.py:290: PytestUnknownMarkWarning: Unknown pytest.mark.security - is this a typo?  You can register custom marks to avoid this warning - for details, see https://docs.pytest.org/en/stable/how-to/mark.html\n    @pytest.mark.security\n\ntests\\test_ui.py:19\n  C:\\Users\\Devansh\\Downloads\\intern_application_round1\\tests\\test_ui.py:19: PytestUnknownMarkWarning: Unknown pytest.mark.unit - is this a typo?  You can register custom marks to avoid this warning - for details, see https://docs.pytest.org/en/stable/how-to/mark.html\n    @pytest.mark.unit\n\ntests\\test_ui.py:27\n  C:\\Users\\Devansh\\Downloads\\intern_application_round1\\tests\\test_ui.py:27: PytestUnknownMarkWarning: Unknown pytest.mark.unit - is this a typo?  You can register custom marks to avoid this warning - for details, see https://docs.pytest.org/en/stable/how-to/mark.html\n    @pytest.mark.unit\n\ntests\\test_ui.py:45\n  C:\\Users\\Devansh\\Downloads\\intern_application_round1\\tests\\test_ui.py:45: PytestUnknownMarkWarning: Unknown pytest.mark.unit - is this a typo?  You can register custom marks to avoid this warning - for details, see https://docs.pytest.org/en/stable/how-to/mark.html\n    @pytest.mark.unit\n\ntests\\test_ui.py:66\n  C:\\Users\\Devansh\\Downloads\\intern_application_round1\\tests\\test_ui.py:66: PytestUnknownMarkWarning: Unknown pytest.mark.unit - is this a typo?  You can register custom marks to avoid this warning - for details, see https://docs.pytest.org/en/stable/how-to/mark.html\n    @pytest.mark.unit\n\ntests\\test_ui.py:87\n  C:\\Users\\Devansh\\Downloads\\intern_application_round1\\tests\\test_ui.py:87: PytestUnknownMarkWarning: Unknown pytest.mark.unit - is this a typo?  You can register custom marks to avoid this warning - for details, see https://docs.pytest.org/en/stable/how-to/mark.html\n    @pytest.mark.unit\n\ntests\\test_ui.py:107\n  C:\\Users\\Devansh\\Downloads\\intern_application_round1\\tests\\test_ui.py:107: PytestUnknownMarkWarning: Unknown pytest.mark.unit - is this a typo?  You can register custom marks to avoid this warning - for details, see https://docs.pytest.org/en/stable/how-to/mark.html\n    @pytest.mark.unit\n\ntests\\test_ui.py:125\n  C:\\Users\\Devansh\\Downloads\\intern_application_round1\\tests\\test_ui.py:125: PytestUnknownMarkWarning: Unknown pytest.mark.unit - is this a typo?  You can register custom marks to avoid this warning - for details, see https://docs.pytest.org/en/stable/how-to/mark.html\n    @pytest.mark.unit\n\ntests\\test_ui.py:140\n  C:\\Users\\Devansh\\Downloads\\intern_application_round1\\tests\\test_ui.py:140: PytestUnknownMarkWarning: Unknown pytest.mark.unit - is this a typo?  You can register custom marks to avoid this warning - for details, see https://docs.pytest.org/en/stable/how-to/mark.html\n    @pytest.mark.unit\n\ntests\\test_ui.py:155\n  C:\\Users\\Devansh\\Downloads\\intern_application_round1\\tests\\test_ui.py:155: PytestUnknownMarkWarning: Unknown pytest.mark.unit - is this a typo?  You can register custom marks to avoid this warning - for details, see https://docs.pytest.org/en/stable/how-to/mark.html\n    @pytest.mark.unit\n\ntests\\test_ui.py:168\n  C:\\Users\\Devansh\\Downloads\\intern_application_round1\\tests\\test_ui.py:168: PytestUnknownMarkWarning: Unknown pytest.mark.unit - is this a typo?  You can register custom marks to avoid this warning - for details, see https://docs.pytest.org/en/stable/how-to/mark.html\n    @pytest.mark.unit\n\ntests\\test_ui.py:183\n  C:\\Users\\Devansh\\Downloads\\intern_application_round1\\tests\\test_ui.py:183: PytestUnknownMarkWarning: Unknown pytest.mark.unit - is this a typo?  You can register custom marks to avoid this warning - for details, see https://docs.pytest.org/en/stable/how-to/mark.html\n    @pytest.mark.unit\n\ntests\\test_ui.py:201\n  C:\\Users\\Devansh\\Downloads\\intern_application_round1\\tests\\test_ui.py:201: PytestUnknownMarkWarning: Unknown pytest.mark.unit - is this a typo?  You can register custom marks to avoid this warning - for details, see https://docs.pytest.org/en/stable/how-to/mark.html\n    @pytest.mark.unit\n\ntests\\test_ui.py:220\n  C:\\Users\\Devansh\\Downloads\\intern_application_round1\\tests\\test_ui.py:220: PytestUnknownMarkWarning: Unknown pytest.mark.unit - is this a typo?  You can register custom marks to avoid this warning - for details, see https://docs.pytest.org/en/stable/how-to/mark.html\n    @pytest.mark.unit\n\ntests\\test_ui.py:231\n  C:\\Users\\Devansh\\Downloads\\intern_application_round1\\tests\\test_ui.py:231: PytestUnknownMarkWarning: Unknown pytest.mark.unit - is this a typo?  You can register custom marks to avoid this warning - for details, see https://docs.pytest.org/en/stable/how-to/mark.html\n    @pytest.mark.unit\n\ntests\\test_ui.py:244\n  C:\\Users\\Devansh\\Downloads\\intern_application_round1\\tests\\test_ui.py:244: PytestUnknownMarkWarning: Unknown pytest.mark.unit - is this a typo?  You can register custom marks to avoid this warning - for details, see https://docs.pytest.org/en/stable/how-to/mark.html\n    @pytest.mark.unit\n\ntests\\test_ui.py:267\n  C:\\Users\\Devansh\\Downloads\\intern_application_round1\\tests\\test_ui.py:267: PytestUnknownMarkWarning: Unknown pytest.mark.unit - is this a typo?  You can register custom marks to avoid this warning - for details, see https://docs.pytest.org/en/stable/how-to/mark.html\n    @pytest.mark.unit\n\ntests\\test_ui.py:292\n  C:\\Users\\Devansh\\Downloads\\intern_application_round1\\tests\\test_ui.py:292: PytestUnknownMarkWarning: Unknown pytest.mark.unit - is this a typo?  You can register custom marks to avoid this warning - for details, see https://docs.pytest.org/en/stable/how-to/mark.html\n    @pytest.mark.unit\n\ntests\\test_ui.py:315\n  C:\\Users\\Devansh\\Downloads\\intern_application_round1\\tests\\test_ui.py:315: PytestUnknownMarkWarning: Unknown pytest.mark.unit - is this a typo?  You can register custom marks to avoid this warning - for details, see https://docs.pytest.org/en/stable/how-to/mark.html\n    @pytest.mark.unit\n\ntests\\test_ui.py:336\n  C:\\Users\\Devansh\\Downloads\\intern_application_round1\\tests\\test_ui.py:336: PytestUnknownMarkWarning: Unknown pytest.mark.unit - is this a typo?  You can register custom marks to avoid this warning - for details, see https://docs.pytest.org/en/stable/how-to/mark.html\n    @pytest.mark.unit\n\ntests\\test_ui.py:357\n  C:\\Users\\Devansh\\Downloads\\intern_application_round1\\tests\\test_ui.py:357: PytestUnknownMarkWarning: Unknown pytest.mark.unit - is this a typo?  You can register custom marks to avoid this warning - for details, see https://docs.pytest.org/en/stable/how-to/mark.html\n    @pytest.mark.unit\n\ntests\\test_ui.py:382\n  C:\\Users\\Devansh\\Downloads\\intern_application_round1\\tests\\test_ui.py:382: PytestUnknownMarkWarning: Unknown pytest.mark.unit - is this a typo?  You can register custom marks to avoid this warning - for details, see https://docs.pytest.org/en/stable/how-to/mark.html\n    @pytest.mark.unit\n\ntests\\test_ui.py:403\n  C:\\Users\\Devansh\\Downloads\\intern_application_round1\\tests\\test_ui.py:403: PytestUnknownMarkWarning: Unknown pytest.mark.unit - is this a typo?  You can register custom marks to avoid this warning - for details, see https://docs.pytest.org/en/stable/how-to/mark.html\n    @pytest.mark.unit\n\ntests\\test_ui.py:427\n  C:\\Users\\Devansh\\Downloads\\intern_application_round1\\tests\\test_ui.py:427: PytestUnknownMarkWarning: Unknown pytest.mark.unit - is this a typo?  You can register custom marks to avoid this warning - for details, see https://docs.pytest.org/en/stable/how-to/mark.html\n    @pytest.mark.unit\n\ntests\\test_ui.py:442\n  C:\\Users\\Devansh\\Downloads\\intern_application_round1\\tests\\test_ui.py:442: PytestUnknownMarkWarning: Unknown pytest.mark.unit - is this a typo?  You can register custom marks to avoid this warning - for details, see https://docs.pytest.org/en/stable/how-to/mark.html\n    @pytest.mark.unit\n\ntests\\test_ui.py:454\n  C:\\Users\\Devansh\\Downloads\\intern_application_round1\\tests\\test_ui.py:454: PytestUnknownMarkWarning: Unknown pytest.mark.unit - is this a typo?  You can register custom marks to avoid this warning - for details, see https://docs.pytest.org/en/stable/how-to/mark.html\n    @pytest.mark.unit\n\ntests\\test_ui.py:476\n  C:\\Users\\Devansh\\Downloads\\intern_application_round1\\tests\\test_ui.py:476: PytestUnknownMarkWarning: Unknown pytest.mark.unit - is this a typo?  You can register custom marks to avoid this warning - for details, see https://docs.pytest.org/en/stable/how-to/mark.html\n    @pytest.mark.unit\n\ntests\\test_ui.py:504\n  C:\\Users\\Devansh\\Downloads\\intern_application_round1\\tests\\test_ui.py:504: PytestUnknownMarkWarning: Unknown pytest.mark.unit - is this a typo?  You can register custom marks to avoid this warning - for details, see https://docs.pytest.org/en/stable/how-to/mark.html\n    @pytest.mark.unit\n\ntests\\test_ui.py:530\n  C:\\Users\\Devansh\\Downloads\\intern_application_round1\\tests\\test_ui.py:530: PytestUnknownMarkWarning: Unknown pytest.mark.unit - is this a typo?  You can register custom marks to avoid this warning - for details, see https://docs.pytest.org/en/stable/how-to/mark.html\n    @pytest.mark.unit\n\ntests/test_analytics.py::TestAnalyticsIntegration::test_full_analytics_pipeline\ntests/test_integration.py::TestSystemIntegration::test_complete_workflow\ntests/test_integration.py::TestSystemIntegration::test_async_workflow\ntests/test_integration.py::TestSystemIntegration::test_data_consistency\ntests/test_integration.py::TestSystemIntegration::test_concurrent_access\n  C:\\Users\\Devansh\\Downloads\\intern_application_round1\\tests\\conftest.py:27: DeprecationWarning: datetime.datetime.utcnow() is deprecated and scheduled for removal in a future version. Use timezone-aware objects to represent datetimes in UTC: datetime.datetime.now(datetime.UTC).\n    'created_utc': datetime.utcnow(),\n\ntests/test_analytics.py::TestAnalyticsIntegration::test_full_analytics_pipeline\ntests/test_integration.py::TestSystemIntegration::test_complete_workflow\ntests/test_integration.py::TestSystemIntegration::test_async_workflow\ntests/test_integration.py::TestSystemIntegration::test_data_consistency\ntests/test_integration.py::TestSystemIntegration::test_concurrent_access\n  C:\\Users\\Devansh\\Downloads\\intern_application_round1\\tests\\conftest.py:30: DeprecationWarning: datetime.datetime.utcnow() is deprecated and scheduled for removal in a future version. Use timezone-aware objects to represent datetimes in UTC: datetime.datetime.now(datetime.UTC).\n    'scraped_at': datetime.utcnow()\n\ntests/test_analytics.py: 110 warnings\n  C:\\Users\\Devansh\\Downloads\\intern_application_round1\\analytics\\data_validator.py:222: DeprecationWarning: datetime.datetime.utcnow() is deprecated and scheduled for removal in a future version. Use timezone-aware objects to represent datetimes in UTC: datetime.datetime.now(datetime.UTC).\n    'validation_timestamp': datetime.utcnow().isoformat()\n\ntests/test_analytics.py: 3 warnings\ntests/test_integration.py: 7 warnings\n  C:\\Users\\Devansh\\AppData\\Roaming\\Python\\Python312\\site-packages\\sqlalchemy\\sql\\schema.py:3616: DeprecationWarning: datetime.datetime.utcnow() is deprecated and scheduled for removal in a future version. Use timezone-aware objects to represent datetimes in UTC: datetime.datetime.now(datetime.UTC).\n    return util.wrap_callable(lambda ctx: fn(), fn)  # type: ignore\n\ntests/test_analytics.py::TestAnalyticsIntegration::test_analytics_with_empty_data\n  C:\\Users\\Devansh\\Downloads\\intern_application_round1\\database\\models.py:140: DeprecationWarning: datetime.datetime.utcnow() is deprecated and scheduled for removal in a future version. Use timezone-aware objects to represent datetimes in UTC: datetime.datetime.now(datetime.UTC).\n    cutoff_date = datetime.utcnow().replace(hour=0, minute=0, second=0, microsecond=0)\n\ntests/test_analytics.py::TestAnalyticsIntegration::test_analytics_performance\n  C:\\Users\\Devansh\\Downloads\\intern_application_round1\\tests\\test_analytics.py:674: DeprecationWarning: datetime.datetime.utcnow() is deprecated and scheduled for removal in a future version. Use timezone-aware objects to represent datetimes in UTC: datetime.datetime.now(datetime.UTC).\n    'created_utc': datetime.utcnow(),\n\ntests/test_integration.py::TestSystemIntegration::test_performance_integration\n  C:\\Users\\Devansh\\Downloads\\intern_application_round1\\tests\\test_integration.py:225: DeprecationWarning: datetime.datetime.utcnow() is deprecated and scheduled for removal in a future version. Use timezone-aware objects to represent datetimes in UTC: datetime.datetime.now(datetime.UTC).\n    'created_utc': datetime.utcnow(),\n\ntests/test_integration.py::TestAPIIntegration::test_api_health_endpoint\n  C:\\Users\\Devansh\\AppData\\Roaming\\Python\\Python312\\site-packages\\pydantic\\fields.py:1017: PydanticDeprecatedSince20: `max_items` is deprecated and will be removed, use `max_length` instead. Deprecated in Pydantic V2.0 to be removed in V3.0. See Pydantic V2 Migration Guide at https://errors.pydantic.dev/2.10/migration/\n    warn('`max_items` is deprecated and will be removed, use `max_length` instead', DeprecationWarning)\n\ntests/test_integration.py::TestAPIIntegration::test_api_health_endpoint\n  C:\\Users\\Devansh\\Downloads\\intern_application_round1\\api\\endpoints.py:115: DeprecationWarning: datetime.datetime.utcnow() is deprecated and scheduled for removal in a future version. Use timezone-aware objects to represent datetimes in UTC: datetime.datetime.now(datetime.UTC).\n    timestamp=datetime.utcnow()\n\ntests/test_integration.py::TestCacheIntegration::test_cache_integration_basic\ntests/test_integration.py::TestCacheIntegration::test_cache_performance_impact\n  C:\\Users\\Devansh\\Downloads\\intern_application_round1\\database\\cache_manager.py:67: DeprecationWarning: datetime.datetime.utcnow() is deprecated and scheduled for removal in a future version. Use timezone-aware objects to represent datetimes in UTC: datetime.datetime.now(datetime.UTC).\n    'timestamp': datetime.utcnow().isoformat(),\n\n-- Docs: https://docs.pytest.org/en/stable/how-to/capture-warnings.html\n=========================== short test summary info ===========================\nFAILED tests/test_analytics.py::TestAnalyticsIntegration::test_full_analytics_pipeline\nFAILED tests/test_analytics.py::TestAnalyticsIntegration::test_analytics_performance\nFAILED tests/test_integration.py::TestSystemIntegration::test_complete_workflow\nFAILED tests/test_integration.py::TestSystemIntegration::test_async_workflow\nFAILED tests/test_integration.py::TestSystemIntegration::test_data_consistency\nFAILED tests/test_integration.py::TestSystemIntegration::test_concurrent_access\nFAILED tests/test_integration.py::TestSystemIntegration::test_performance_integration\nFAILED tests/test_integration.py::TestAPIIntegration::test_api_search_endpoint\nFAILED tests/test_integration.py::TestCacheIntegration::test_cache_integration_basic\nFAILED tests/test_integration.py::TestCacheIntegration::test_cache_performance_impact\nERROR tests/test_integration.py::TestSystemIntegration::test_complete_workflow\nERROR tests/test_integration.py::TestSystemIntegration::test_async_workflow\nERROR tests/test_integration.py::TestSystemIntegration::test_error_propagation\nERROR tests/test_integration.py::TestSystemIntegration::test_data_consistency\nERROR tests/test_integration.py::TestSystemIntegration::test_concurrent_access\nERROR tests/test_integration.py::TestSystemIntegration::test_performance_integration\nERROR tests/test_integration.py::TestEndToEndWorkflow::test_complete_user_workflow\nERROR tests/test_integration.py::TestEndToEndWorkflow::test_error_recovery_workflow\nERROR tests/test_integration.py::TestEndToEndWorkflow::test_scalability_workflow\n==== 10 failed, 6 passed, 145 deselected, 258 warnings, 9 errors in 10.18s ====\n",
      "stderr": "Windows fatal exception: access violation\n\nCurrent thread 0x000079f4 (most recent call first):\n  File \"<frozen importlib._bootstrap>\", line 488 in _call_with_frames_removed\n  File \"<frozen importlib._bootstrap_external>\", line 1288 in create_module\n  File \"<frozen importlib._bootstrap>\", line 813 in module_from_spec\n  File \"<frozen importlib._bootstrap>\", line 921 in _load_unlocked\n  File \"<frozen importlib._bootstrap>\", line 1331 in _find_and_load_unlocked\n  File \"<frozen importlib._bootstrap>\", line 1360 in _find_and_load\n  File \"C:\\Users\\Devansh\\AppData\\Roaming\\Python\\Python312\\site-packages\\tensorflow\\python\\pywrap_tensorflow.py\", line 73 in <module>\n  File \"<frozen importlib._bootstrap>\", line 488 in _call_with_frames_removed\n  File \"<frozen importlib._bootstrap_external>\", line 994 in exec_module\n  File \"<frozen importlib._bootstrap>\", line 935 in _load_unlocked\n  File \"<frozen importlib._bootstrap>\", line 1331 in _find_and_load_unlocked\n  File \"<frozen importlib._bootstrap>\", line 1360 in _find_and_load\n  File \"<frozen importlib._bootstrap>\", line 488 in _call_with_frames_removed\n  File \"<frozen importlib._bootstrap>\", line 1415 in _handle_fromlist\n  File \"C:\\Users\\Devansh\\AppData\\Roaming\\Python\\Python312\\site-packages\\tensorflow\\__init__.py\", line 40 in <module>\n  File \"<frozen importlib._bootstrap>\", line 488 in _call_with_frames_removed\n  File \"<frozen importlib._bootstrap_external>\", line 994 in exec_module\n  File \"<frozen importlib._bootstrap>\", line 935 in _load_unlocked\n  File \"<frozen importlib._bootstrap>\", line 1331 in _find_and_load_unlocked\n  File \"<frozen importlib._bootstrap>\", line 1360 in _find_and_load\n  File \"C:\\Users\\Devansh\\AppData\\Roaming\\Python\\Python312\\site-packages\\transformers\\image_transforms.py\", line 47 in <module>\n  File \"<frozen importlib._bootstrap>\", line 488 in _call_with_frames_removed\n  File \"<frozen importlib._bootstrap_external>\", line 994 in exec_module\n  File \"<frozen importlib._bootstrap>\", line 935 in _load_unlocked\n  File \"<frozen importlib._bootstrap>\", line 1331 in _find_and_load_unlocked\n  File \"<frozen importlib._bootstrap>\", line 1360 in _find_and_load\n  File \"C:\\Users\\Devansh\\AppData\\Roaming\\Python\\Python312\\site-packages\\transformers\\image_processing_utils.py\", line 22 in <module>\n  File \"<frozen importlib._bootstrap>\", line 488 in _call_with_frames_removed\n  File \"<frozen importlib._bootstrap_external>\", line 994 in exec_module\n  File \"<frozen importlib._bootstrap>\", line 935 in _load_unlocked\n  File \"<frozen importlib._bootstrap>\", line 1331 in _find_and_load_unlocked\n  File \"<frozen importlib._bootstrap>\", line 1360 in _find_and_load\n  File \"C:\\Users\\Devansh\\AppData\\Roaming\\Python\\Python312\\site-packages\\transformers\\pipelines\\__init__.py\", line 26 in <module>\n  File \"<frozen importlib._bootstrap>\", line 488 in _call_with_frames_removed\n  File \"<frozen importlib._bootstrap_external>\", line 994 in exec_module\n  File \"<frozen importlib._bootstrap>\", line 935 in _load_unlocked\n  File \"<frozen importlib._bootstrap>\", line 1331 in _find_and_load_unlocked\n  File \"<frozen importlib._bootstrap>\", line 1360 in _find_and_load\n  File \"<frozen importlib._bootstrap>\", line 1387 in _gcd_import\n  File \"C:\\Program Files\\Python312\\Lib\\importlib\\__init__.py\", line 90 in import_module\n  File \"C:\\Users\\Devansh\\AppData\\Roaming\\Python\\Python312\\site-packages\\transformers\\utils\\import_utils.py\", line 2073 in _get_module\n  File \"C:\\Users\\Devansh\\AppData\\Roaming\\Python\\Python312\\site-packages\\transformers\\utils\\import_utils.py\", line 2045 in __getattr__\n  File \"<frozen importlib._bootstrap>\", line 1412 in _handle_fromlist\n  File \"C:\\Users\\Devansh\\Downloads\\intern_application_round1\\analytics\\advanced_sentiment.py\", line 12 in <module>\n  File \"<frozen importlib._bootstrap>\", line 488 in _call_with_frames_removed\n  File \"<frozen importlib._bootstrap_external>\", line 994 in exec_module\n  File \"<frozen importlib._bootstrap>\", line 935 in _load_unlocked\n  File \"<frozen importlib._bootstrap>\", line 1331 in _find_and_load_unlocked\n  File \"<frozen importlib._bootstrap>\", line 1360 in _find_and_load\n  File \"C:\\Users\\Devansh\\Downloads\\intern_application_round1\\api\\endpoints.py\", line 19 in <module>\n  File \"<frozen importlib._bootstrap>\", line 488 in _call_with_frames_removed\n  File \"<frozen importlib._bootstrap_external>\", line 994 in exec_module\n  File \"<frozen importlib._bootstrap>\", line 935 in _load_unlocked\n  File \"<frozen importlib._bootstrap>\", line 1331 in _find_and_load_unlocked\n  File \"<frozen importlib._bootstrap>\", line 1360 in _find_and_load\n  File \"C:\\Users\\Devansh\\Downloads\\intern_application_round1\\tests\\test_integration.py\", line 250 in api_client\n  File \"C:\\Users\\Devansh\\AppData\\Roaming\\Python\\Python312\\site-packages\\_pytest\\fixtures.py\", line 898 in call_fixture_func\n  File \"C:\\Users\\Devansh\\AppData\\Roaming\\Python\\Python312\\site-packages\\_pytest\\fixtures.py\", line 1140 in pytest_fixture_setup\n  File \"C:\\Users\\Devansh\\AppData\\Roaming\\Python\\Python312\\site-packages\\pluggy\\_callers.py\", line 103 in _multicall\n  File \"C:\\Users\\Devansh\\AppData\\Roaming\\Python\\Python312\\site-packages\\pluggy\\_manager.py\", line 120 in _hookexec\n  File \"C:\\Users\\Devansh\\AppData\\Roaming\\Python\\Python312\\site-packages\\pluggy\\_hooks.py\", line 513 in __call__\n  File \"C:\\Users\\Devansh\\AppData\\Roaming\\Python\\Python312\\site-packages\\_pytest\\fixtures.py\", line 1091 in execute\n  File \"C:\\Users\\Devansh\\AppData\\Roaming\\Python\\Python312\\site-packages\\_pytest\\fixtures.py\", line 617 in _get_active_fixturedef\n  File \"C:\\Users\\Devansh\\AppData\\Roaming\\Python\\Python312\\site-packages\\_pytest\\fixtures.py\", line 532 in getfixturevalue\n  File \"C:\\Users\\Devansh\\AppData\\Roaming\\Python\\Python312\\site-packages\\_pytest\\fixtures.py\", line 697 in _fillfixtures\n  File \"C:\\Users\\Devansh\\AppData\\Roaming\\Python\\Python312\\site-packages\\_pytest\\python.py\", line 1630 in setup\n  File \"C:\\Users\\Devansh\\AppData\\Roaming\\Python\\Python312\\site-packages\\_pytest\\runner.py\", line 514 in setup\n  File \"C:\\Users\\Devansh\\AppData\\Roaming\\Python\\Python312\\site-packages\\_pytest\\runner.py\", line 160 in pytest_runtest_setup\n  File \"C:\\Users\\Devansh\\AppData\\Roaming\\Python\\Python312\\site-packages\\pluggy\\_callers.py\", line 103 in _multicall\n  File \"C:\\Users\\Devansh\\AppData\\Roaming\\Python\\Python312\\site-packages\\pluggy\\_manager.py\", line 120 in _hookexec\n  File \"C:\\Users\\Devansh\\AppData\\Roaming\\Python\\Python312\\site-packages\\pluggy\\_hooks.py\", line 513 in __call__\n  File \"C:\\Users\\Devansh\\AppData\\Roaming\\Python\\Python312\\site-packages\\_pytest\\runner.py\", line 242 in <lambda>\n  File \"C:\\Users\\Devansh\\AppData\\Roaming\\Python\\Python312\\site-packages\\_pytest\\runner.py\", line 341 in from_call\n  File \"C:\\Users\\Devansh\\AppData\\Roaming\\Python\\Python312\\site-packages\\_pytest\\runner.py\", line 241 in call_and_report\n  File \"C:\\Users\\Devansh\\AppData\\Roaming\\Python\\Python312\\site-packages\\_pytest\\runner.py\", line 126 in runtestprotocol\n  File \"C:\\Users\\Devansh\\AppData\\Roaming\\Python\\Python312\\site-packages\\_pytest\\runner.py\", line 113 in pytest_runtest_protocol\n  File \"C:\\Users\\Devansh\\AppData\\Roaming\\Python\\Python312\\site-packages\\pluggy\\_callers.py\", line 103 in _multicall\n  File \"C:\\Users\\Devansh\\AppData\\Roaming\\Python\\Python312\\site-packages\\pluggy\\_manager.py\", line 120 in _hookexec\n  File \"C:\\Users\\Devansh\\AppData\\Roaming\\Python\\Python312\\site-packages\\pluggy\\_hooks.py\", line 513 in __call__\n  File \"C:\\Users\\Devansh\\AppData\\Roaming\\Python\\Python312\\site-packages\\_pytest\\main.py\", line 362 in pytest_runtestloop\n  File \"C:\\Users\\Devansh\\AppData\\Roaming\\Python\\Python312\\site-packages\\pluggy\\_callers.py\", line 103 in _multicall\n  File \"C:\\Users\\Devansh\\AppData\\Roaming\\Python\\Python312\\site-packages\\pluggy\\_manager.py\", line 120 in _hookexec\n  File \"C:\\Users\\Devansh\\AppData\\Roaming\\Python\\Python312\\site-packages\\pluggy\\_hooks.py\", line 513 in __call__\n  File \"C:\\Users\\Devansh\\AppData\\Roaming\\Python\\Python312\\site-packages\\_pytest\\main.py\", line 337 in _main\n  File \"C:\\Users\\Devansh\\AppData\\Roaming\\Python\\Python312\\site-packages\\_pytest\\main.py\", line 283 in wrap_session\n  File \"C:\\Users\\Devansh\\AppData\\Roaming\\Python\\Python312\\site-packages\\_pytest\\main.py\", line 330 in pytest_cmdline_main\n  File \"C:\\Users\\Devansh\\AppData\\Roaming\\Python\\Python312\\site-packages\\pluggy\\_callers.py\", line 103 in _multicall\n  File \"C:\\Users\\Devansh\\AppData\\Roaming\\Python\\Python312\\site-packages\\pluggy\\_manager.py\", line 120 in _hookexec\n  File \"C:\\Users\\Devansh\\AppData\\Roaming\\Python\\Python312\\site-packages\\pluggy\\_hooks.py\", line 513 in __call__\n  File \"C:\\Users\\Devansh\\AppData\\Roaming\\Python\\Python312\\site-packages\\_pytest\\config\\__init__.py\", line 175 in main\n  File \"C:\\Users\\Devansh\\AppData\\Roaming\\Python\\Python312\\site-packages\\_pytest\\config\\__init__.py\", line 201 in console_main\n  File \"C:\\Users\\Devansh\\AppData\\Roaming\\Python\\Python312\\site-packages\\pytest\\__main__.py\", line 9 in <module>\n  File \"<frozen runpy>\", line 88 in _run_code\n  File \"<frozen runpy>\", line 198 in _run_module_as_main\n",
      "critical": true
    }
  },
  "system_status": "needs_attention"
}